Workbook

Sheet دليل Pro
A1: Diet Pro Athlete — نظام تغذية الرياضيين بالجرام (مستقل)
A2: لا يستبدل التقييم السريري أو الحكم المهني لأخصائي التغذية.
A4: 1) «Pro ملف الرياضي»: أدخل بيانات الرياضي (اسم، جنس، عمر، وزن، طول) واختر المرحلة وأدخل نوع كل يوم ومدة التدريب؛ تظهر أهداف كل يوم بالجرام.
A5: 2) «Pro مخطط الأسبوع»: لكل وجبة اختر الصنف واكتب الجرامات؛ يظهر مجموع الوجبة ومجموع اليوم والفرق عن الهدف.
A6: 3) «Pro باني الوجبة»: اكتب هدف الوجبة بالجرام واختر مصادر البروتين والكارب والدهون فيحسب الجرامات.
A7: 4) «Pro قاعدة الأغذية»: 122 صنفاً من USDA لكل 100 جم؛ أضف أصنافاً من Pro_Foods_Database.xlsx.
A8: 5) «Pro إعدادات» و«Pro إرشادات المراحل»: كل القيم والعبارات قابلة للتعديل.
A9: 6) احفظ الملف (Ctrl+S) ثم شغّل: python make_pro_word.py --xlsx Diet_Pro_Athlete.xlsx --out Pro_Plan.docx

Sheet Pro ملف الرياضي
A1: Pro — ملف الرياضي والأهداف بالجرام
A2: يعمل بالجرام وبشكل مستقل عن نظام الحصص. الاسم والجنس والعمر والوزن والطول تُؤخذ من صفحة العميل. أدخل المرحلة وجدول الأسبوع (الخلايا الصفراء).
A4: الاسم | B4: رياضي تجريبي
A5: الجنس | B5: ذكر
A6: العمر | B6: 28
A7: الوزن (كجم) | B7: 80
A8: الطول (سم) | B8: 178
A9: نسبة الدهون % (اختياري — تفعّل معادلة الكتلة الخالية)
A10: الرياضة | B10: كمال أجسام
A11: المرحلة | B11: تثبيت / صيانة
A12: طريقة حساب الكارب | B12: حسب حمل التدريب (g/kg)
A14: الكتلة الخالية FFM (كجم) | B14: =IF(B9="","",B7*(1-B9))
A15: BMR | B15: =IF(B9="",IF(B5="ذكر",10*B7+6.25*B8-5*B6+5,10*B7+6.25*B8-5*B6-161),370+21.6*B14) -> 1777.5
A16: طريقة BMR | B16: =IF(B9="","Mifflin-St Jeor (لا توجد نسبة دهون)","Cunningham (كتلة خالية)") -> Mifflin-St Jeor (لا توجد نسبة دهون)
A17: بروتين g/kg (المرحلة) | B17: =INDEX('Pro إعدادات'!$B$5:$B$10,MATCH(B11,'Pro إعدادات'!$A$5:$A$10,0)) -> 1.8
A18: دهون g/kg (المرحلة) | B18: =INDEX('Pro إعدادات'!$C$5:$C$10,MATCH(B11,'Pro إعدادات'!$A$5:$A$10,0)) -> 0.9
A19: تعديل سعرات المرحلة | B19: =INDEX('Pro إعدادات'!$D$5:$D$10,MATCH(B11,'Pro إعدادات'!$A$5:$A$10,0)) -> 0
A21: جدول الأسبوع والأهداف بالجرام
A22: اليوم | B22: نوع اليوم | C22: مدة التدريب (د) | D22: وقت التدريب | E22: سعرات التدريب | F22: TDEE | G22: سعرات الهدف | H22: بروتين g | I22: كارب g | J22: دهون g | K22: kcal الماكروز | L22: فرق عن الهدف | M22: كارب g/kg | N22: ماء (لتر) | O22: EA kcal/kg FFM | P22: تحذيرات
A23: الأحد | B23: تدريب ثقيل | C23: 75 | D23: 17:00 | E23: =C23*INDEX('Pro إعدادات'!$C$14:$C$19,MATCH(B23,'Pro إعدادات'!$A$14:$A$19,0)) -> 525 | F23: =$B$15*'Pro إعدادات'!$B$22+E23 -> 2835.75 | G23: =F23*(1+$B$19) -> 2835.75 | H23: =$B$17*$B$7 -> 144 | I23: =IF($B$12="حسب حمل التدريب (g/kg)",INDEX('Pro إعدادات'!$B$14:$B$19,MATCH(B23,'Pro إعدادات'!$A$14:$A$19,0))*$B$7,MAX(0,(G23-4*H23-9*J23)/4)) -> 480 | J23: =$B$18*$B$7 -> 72 | K23: =4*H23+4*I23+9*J23 -> 3144 | L23: =K23-G23 -> 308.25 | M23: =IF($B$7>0,I23/$B$7,"") -> 6 | N23: =('Pro إعدادات'!$B$26*$B$7+'Pro إعدادات'!$B$27*C23/60)/1000 -> 3.425 | O23: =IF($B$14="","",(K23-E23)/$B$14) | P23: =TRIM(IF(K23<$B$15,"⚠ السعرات أقل من BMR؛ ","")&IF(H23/$B$7<'Pro إعدادات'!$B$23,"⚠ بروتين منخفض؛ ","")&IF(J23/$B$7<'Pro إعدادات'!$B$24,"⚠ دهون منخفضة؛ ","")&IF(M23<'Pro إعدادات'!$B$29,"⚠ كارب منخفض؛ ","")&IF(AND(O23<>"",N(O23)<'Pro إعدادات'!$B$25),"⚠ طاقة متاحة منخفضة (RED-S)؛ ","")&IF(ABS(L23)>G23*0.1,"ℹ سعرات الماكروز تختلف عن هدف TDEE بأكثر من 10%؛ ","")) -> ℹ سعرات الماكروز تختلف عن هدف TDEE بأكثر من 10%؛
A24: الاثنين | B24: تدريب متوسط | C24: 60 | D24: 17:00 | E24: =C24*INDEX('Pro إعدادات'!$C$14:$C$19,MATCH(B24,'Pro إعدادات'!$A$14:$A$19,0)) -> 360 | F24: =$B$15*'Pro إعدادات'!$B$22+E24 -> 2670.75 | G24: =F24*(1+$B$19) -> 2670.75 | H24: =$B$17*$B$7 -> 144 | I24: =IF($B$12="حسب حمل التدريب (g/kg)",INDEX('Pro إعدادات'!$B$14:$B$19,MATCH(B24,'Pro إعدادات'!$A$14:$A$19,0))*$B$7,MAX(0,(G24-4*H24-9*J24)/4)) -> 400 | J24: =$B$18*$B$7 -> 72 | K24: =4*H24+4*I24+9*J24 -> 2824 | L24: =K24-G24 -> 153.25 | M24: =IF($B$7>0,I24/$B$7,"") -> 5 | N24: =('Pro إعدادات'!$B$26*$B$7+'Pro إعدادات'!$B$27*C24/60)/1000 -> 3.3 | O24: =IF($B$14="","",(K24-E24)/$B$14) | P24: =TRIM(IF(K24<$B$15,"⚠ السعرات أقل من BMR؛ ","")&IF(H24/$B$7<'Pro إعدادات'!$B$23,"⚠ بروتين منخفض؛ ","")&IF(J24/$B$7<'Pro إعدادات'!$B$24,"⚠ دهون منخفضة؛ ","")&IF(M24<'Pro إعدادات'!$B$29,"⚠ كارب منخفض؛ ","")&IF(AND(O24<>"",N(O24)<'Pro إعدادات'!$B$25),"⚠ طاقة متاحة منخفضة (RED-S)؛ ","")&IF(ABS(L24)>G24*0.1,"ℹ سعرات الماكروز تختلف عن هدف TDEE بأكثر من 10%؛ ",""))
A25: الثلاثاء | B25: راحة | C25: 0 | E25: =C25*INDEX('Pro إعدادات'!$C$14:$C$19,MATCH(B25,'Pro إعدادات'!$A$14:$A$19,0)) -> 0 | F25: =$B$15*'Pro إعدادات'!$B$22+E25 -> 2310.75 | G25: =F25*(1+$B$19) -> 2310.75 | H25: =$B$17*$B$7 -> 144 | I25: =IF($B$12="حسب حمل التدريب (g/kg)",INDEX('Pro إعدادات'!$B$14:$B$19,MATCH(B25,'Pro إعدادات'!$A$14:$A$19,0))*$B$7,MAX(0,(G25-4*H25-9*J25)/4)) -> 240 | J25: =$B$18*$B$7 -> 72 | K25: =4*H25+4*I25+9*J25 -> 2184 | L25: =K25-G25 -> -126.75 | M25: =IF($B$7>0,I25/$B$7,"") -> 3 | N25: =('Pro إعدادات'!$B$26*$B$7+'Pro إعدادات'!$B$27*C25/60)/1000 -> 2.8 | O25: =IF($B$14="","",(K25-E25)/$B$14) | P25: =TRIM(IF(K25<$B$15,"⚠ السعرات أقل من BMR؛ ","")&IF(H25/$B$7<'Pro إعدادات'!$B$23,"⚠ بروتين منخفض؛ ","")&IF(J25/$B$7<'Pro إعدادات'!$B$24,"⚠ دهون منخفضة؛ ","")&IF(M25<'Pro إعدادات'!$B$29,"⚠ كارب منخفض؛ ","")&IF(AND(O25<>"",N(O25)<'Pro إعدادات'!$B$25),"⚠ طاقة متاحة منخفضة (RED-S)؛ ","")&IF(ABS(L25)>G25*0.1,"ℹ سعرات الماكروز تختلف عن هدف TDEE بأكثر من 10%؛ ",""))
A26: الأربعاء | B26: تدريب ثقيل | C26: 75 | D26: 17:00 | E26: =C26*INDEX('Pro إعدادات'!$C$14:$C$19,MATCH(B26,'Pro إعدادات'!$A$14:$A$19,0)) -> 525 | F26: =$B$15*'Pro إعدادات'!$B$22+E26 -> 2835.75 | G26: =F26*(1+$B$19) -> 2835.75 | H26: =$B$17*$B$7 -> 144 | I26: =IF($B$12="حسب حمل التدريب (g/kg)",INDEX('Pro إعدادات'!$B$14:$B$19,MATCH(B26,'Pro إعدادات'!$A$14:$A$19,0))*$B$7,MAX(0,(G26-4*H26-9*J26)/4)) -> 480 | J26: =$B$18*$B$7 -> 72 | K26: =4*H26+4*I26+9*J26 -> 3144 | L26: =K26-G26 -> 308.25 | M26: =IF($B$7>0,I26/$B$7,"") -> 6 | N26: =('Pro إعدادات'!$B$26*$B$7+'Pro إعدادات'!$B$27*C26/60)/1000 -> 3.425 | O26: =IF($B$14="","",(K26-E26)/$B$14) | P26: =TRIM(IF(K26<$B$15,"⚠ السعرات أقل من BMR؛ ","")&IF(H26/$B$7<'Pro إعدادات'!$B$23,"⚠ بروتين منخفض؛ ","")&IF(J26/$B$7<'Pro إعدادات'!$B$24,"⚠ دهون منخفضة؛ ","")&IF(M26<'Pro إعدادات'!$B$29,"⚠ كارب منخفض؛ ","")&IF(AND(O26<>"",N(O26)<'Pro إعدادات'!$B$25),"⚠ طاقة متاحة منخفضة (RED-S)؛ ","")&IF(ABS(L26)>G26*0.1,"ℹ سعرات الماكروز تختلف عن هدف TDEE بأكثر من 10%؛ ","")) -> ℹ سعرات الماكروز تختلف عن هدف TDEE بأكثر من 10%؛
A27: الخميس | B27: تدريب متوسط | C27: 60 | D27: 17:00 | E27: =C27*INDEX('Pro إعدادات'!$C$14:$C$19,MATCH(B27,'Pro إعدادات'!$A$14:$A$19,0)) -> 360 | F27: =$B$15*'Pro إعدادات'!$B$22+E27 -> 2670.75 | G27: =F27*(1+$B$19) -> 2670.75 | H27: =$B$17*$B$7 -> 144 | I27: =IF($B$12="حسب حمل التدريب (g/kg)",INDEX('Pro إعدادات'!$B$14:$B$19,MATCH(B27,'Pro إعدادات'!$A$14:$A$19,0))*$B$7,MAX(0,(G27-4*H27-9*J27)/4)) -> 400 | J27: =$B$18*$B$7 -> 72 | K27: =4*H27+4*I27+9*J27 -> 2824 | L27: =K27-G27 -> 153.25 | M27: =IF($B$7>0,I27/$B$7,"") -> 5 | N27: =('Pro إعدادات'!$B$26*$B$7+'Pro إعدادات'!$B$27*C27/60)/1000 -> 3.3 | O27: =IF($B$14="","",(K27-E27)/$B$14) | P27: =TRIM(IF(K27<$B$15,"⚠ السعرات أقل من BMR؛ ","")&IF(H27/$B$7<'Pro إعدادات'!$B$23,"⚠ بروتين منخفض؛ ","")&IF(J27/$B$7<'Pro إعدادات'!$B$24,"⚠ دهون منخفضة؛ ","")&IF(M27<'Pro إعدادات'!$B$29,"⚠ كارب منخفض؛ ","")&IF(AND(O27<>"",N(O27)<'Pro إعدادات'!$B$25),"⚠ طاقة متاحة منخفضة (RED-S)؛ ","")&IF(ABS(L27)>G27*0.1,"ℹ سعرات الماكروز تختلف عن هدف TDEE بأكثر من 10%؛ ",""))
A28: الجمعة | B28: راحة | C28: 0 | E28: =C28*INDEX('Pro إعدادات'!$C$14:$C$19,MATCH(B28,'Pro إعدادات'!$A$14:$A$19,0)) -> 0 | F28: =$B$15*'Pro إعدادات'!$B$22+E28 -> 2310.75 | G28: =F28*(1+$B$19) -> 2310.75 | H28: =$B$17*$B$7 -> 144 | I28: =IF($B$12="حسب حمل التدريب (g/kg)",INDEX('Pro إعدادات'!$B$14:$B$19,MATCH(B28,'Pro إعدادات'!$A$14:$A$19,0))*$B$7,MAX(0,(G28-4*H28-9*J28)/4)) -> 240 | J28: =$B$18*$B$7 -> 72 | K28: =4*H28+4*I28+9*J28 -> 2184 | L28: =K28-G28 -> -126.75 | M28: =IF($B$7>0,I28/$B$7,"") -> 3 | N28: =('Pro إعدادات'!$B$26*$B$7+'Pro إعدادات'!$B$27*C28/60)/1000 -> 2.8 | O28: =IF($B$14="","",(K28-E28)/$B$14) | P28: =TRIM(IF(K28<$B$15,"⚠ السعرات أقل من BMR؛ ","")&IF(H28/$B$7<'Pro إعدادات'!$B$23,"⚠ بروتين منخفض؛ ","")&IF(J28/$B$7<'Pro إعدادات'!$B$24,"⚠ دهون منخفضة؛ ","")&IF(M28<'Pro إعدادات'!$B$29,"⚠ كارب منخفض؛ ","")&IF(AND(O28<>"",N(O28)<'Pro إعدادات'!$B$25),"⚠ طاقة متاحة منخفضة (RED-S)؛ ","")&IF(ABS(L28)>G28*0.1,"ℹ سعرات الماكروز تختلف عن هدف TDEE بأكثر من 10%؛ ",""))
A29: السبت | B29: تدريب خفيف | C29: 45 | D29: 10:00 | E29: =C29*INDEX('Pro إعدادات'!$C$14:$C$19,MATCH(B29,'Pro إعدادات'!$A$14:$A$19,0)) -> 225 | F29: =$B$15*'Pro إعدادات'!$B$22+E29 -> 2535.75 | G29: =F29*(1+$B$19) -> 2535.75 | H29: =$B$17*$B$7 -> 144 | I29: =IF($B$12="حسب حمل التدريب (g/kg)",INDEX('Pro إعدادات'!$B$14:$B$19,MATCH(B29,'Pro إعدادات'!$A$14:$A$19,0))*$B$7,MAX(0,(G29-4*H29-9*J29)/4)) -> 320 | J29: =$B$18*$B$7 -> 72 | K29: =4*H29+4*I29+9*J29 -> 2504 | L29: =K29-G29 -> -31.75 | M29: =IF($B$7>0,I29/$B$7,"") -> 4 | N29: =('Pro إعدادات'!$B$26*$B$7+'Pro إعدادات'!$B$27*C29/60)/1000 -> 3.175 | O29: =IF($B$14="","",(K29-E29)/$B$14) | P29: =TRIM(IF(K29<$B$15,"⚠ السعرات أقل من BMR؛ ","")&IF(H29/$B$7<'Pro إعدادات'!$B$23,"⚠ بروتين منخفض؛ ","")&IF(J29/$B$7<'Pro إعدادات'!$B$24,"⚠ دهون منخفضة؛ ","")&IF(M29<'Pro إعدادات'!$B$29,"⚠ كارب منخفض؛ ","")&IF(AND(O29<>"",N(O29)<'Pro إعدادات'!$B$25),"⚠ طاقة متاحة منخفضة (RED-S)؛ ","")&IF(ABS(L29)>G29*0.1,"ℹ سعرات الماكروز تختلف عن هدف TDEE بأكثر من 10%؛ ",""))
A31: متوسط الأسبوع | E31: =AVERAGE(E23:E29) -> 285 | F31: =AVERAGE(F23:F29) -> 2595.75 | G31: =AVERAGE(G23:G29) -> 2595.75 | H31: =AVERAGE(H23:H29) -> 144 | I31: =AVERAGE(I23:I29) -> 365.71429 | J31: =AVERAGE(J23:J29) -> 72 | K31: =AVERAGE(K23:K29) -> 2686.8571 | N31: =AVERAGE(N23:N29) -> 3.175
A33: بيانات الخطة (تظهر في ملف Word)
A34: تاريخ الخطة | B34: 46306
A35: اسم الأخصائي / العيادة | B35: اسم الأخصائي
A36: رقم التواصل / واتساب
A37: تاريخ المتابعة القادمة | B37: 46320
A38: هدف الرياضي (بكلماته) | B38: الوصول لأفضل لياقة وشكل
A39: وزن الهدف (كجم)
A40: مدة المرحلة (أسابيع) | B40: 8
A41: ملاحظة الأخصائي للرياضي

Sheet Pro مخطط الأسبوع
A1: Pro — مخطط الوجبات بالجرام (مجموع كل وجبة + مجموع اليوم)
A2: لكل وجبة اختر الصنف (قائمة من «Pro قاعدة الأغذية») واكتب الجرامات؛ تُحسب السعرات والماكروز تلقائياً، مع مجموع الوجبة ومجموع اليوم والفرق عن الهدف (أخضر = ضمن السماحية).
A4: ="الأحد — "&'Pro ملف الرياضي'!B23&" | الهدف: "&ROUND('Pro ملف الرياضي'!G23,0)&" kcal • بروتين "&ROUND('Pro ملف الرياضي'!H23,0)&" جم • كارب "&ROUND('Pro ملف الرياضي'!I23,0)&" جم • دهون "&ROUND('Pro ملف الرياضي'!J23,0)&" جم" -> الأحد — تدريب ثقيل | الهدف: 2836 kcal • بروتين 144 جم • كارب 480 جم • دهون 72 جم | T4: =IF(INDEX('Pro إعدادات'!$D$14:$D$19,MATCH('Pro ملف الرياضي'!B23,'Pro إعدادات'!$A$14:$A$19,0))="نعم",1,0) -> 1
A5: الوجبة | B5: الصنف | C5: جرام | D5: kcal | E5: بروتين g | F5: كارب g | G5: دهون g | H5: ألياف g | I5: صوديوم mg | J5: الحالة | K5: هدف بروتين | L5: هدف كارب | M5: هدف دهون | N5: هدف kcal | O5: فرق بروتين | P5: فرق كارب | Q5: فرق دهون
A6: ='Pro إعدادات'!A33&" ("&'Pro إعدادات'!B33&")" -> الإفطار (07:30) | B6: شوفان جاف | C6: 90 | D6: =IF(OR($S6="",N($C6)=0),"",$C6/100*N(INDEX('Pro قاعدة الأغذية'!$F$5:$F$604,$S6))) -> 341.1 | E6: =IF(OR($S6="",N($C6)=0),"",$C6/100*N(INDEX('Pro قاعدة الأغذية'!$G$5:$G$604,$S6))) -> 11.88 | F6: =IF(OR($S6="",N($C6)=0),"",$C6/100*N(INDEX('Pro قاعدة الأغذية'!$H$5:$H$604,$S6))) -> 60.93 | G6: =IF(OR($S6="",N($C6)=0),"",$C6/100*N(INDEX('Pro قاعدة الأغذية'!$I$5:$I$604,$S6))) -> 5.868 | H6: =IF(OR($S6="",N($C6)=0),"",$C6/100*N(INDEX('Pro قاعدة الأغذية'!$J$5:$J$604,$S6))) -> 9.09 | I6: =IF(OR($S6="",N($C6)=0),"",$C6/100*N(INDEX('Pro قاعدة الأغذية'!$L$5:$L$604,$S6))) -> 5.4 | J6: =IF($S6="","",INDEX('Pro قاعدة الأغذية'!$E$5:$E$604,$S6)) -> مجفّف/جاف | S6: =IF(B6="","",IFERROR(MATCH(B6,'Pro قاعدة الأغذية'!$C$5:$C$604,0),"")) -> 12
B7: بيض كامل مسلوق | C7: 100 | D7: =IF(OR($S7="",N($C7)=0),"",$C7/100*N(INDEX('Pro قاعدة الأغذية'!$F$5:$F$604,$S7))) -> 155 | E7: =IF(OR($S7="",N($C7)=0),"",$C7/100*N(INDEX('Pro قاعدة الأغذية'!$G$5:$G$604,$S7))) -> 12.6 | F7: =IF(OR($S7="",N($C7)=0),"",$C7/100*N(INDEX('Pro قاعدة الأغذية'!$H$5:$H$604,$S7))) -> 1.12 | G7: =IF(OR($S7="",N($C7)=0),"",$C7/100*N(INDEX('Pro قاعدة الأغذية'!$I$5:$I$604,$S7))) -> 10.6 | H7: =IF(OR($S7="",N($C7)=0),"",$C7/100*N(INDEX('Pro قاعدة الأغذية'!$J$5:$J$604,$S7))) -> 0 | I7: =IF(OR($S7="",N($C7)=0),"",$C7/100*N(INDEX('Pro قاعدة الأغذية'!$L$5:$L$604,$S7))) -> 124 | J7: =IF($S7="","",INDEX('Pro قاعدة الأغذية'!$E$5:$E$604,$S7)) -> مطبوخ | S7: =IF(B7="","",IFERROR(MATCH(B7,'Pro قاعدة الأغذية'!$C$5:$C$604,0),"")) -> 42
B8: موز | C8: 120 | D8: =IF(OR($S8="",N($C8)=0),"",$C8/100*N(INDEX('Pro قاعدة الأغذية'!$F$5:$F$604,$S8))) -> 106.8 | E8: =IF(OR($S8="",N($C8)=0),"",$C8/100*N(INDEX('Pro قاعدة الأغذية'!$G$5:$G$604,$S8))) -> 1.308 | F8: =IF(OR($S8="",N($C8)=0),"",$C8/100*N(INDEX('Pro قاعدة الأغذية'!$H$5:$H$604,$S8))) -> 27.36 | G8: =IF(OR($S8="",N($C8)=0),"",$C8/100*N(INDEX('Pro قاعدة الأغذية'!$I$5:$I$604,$S8))) -> 0.396 | H8: =IF(OR($S8="",N($C8)=0),"",$C8/100*N(INDEX('Pro قاعدة الأغذية'!$J$5:$J$604,$S8))) -> 3.12 | I8: =IF(OR($S8="",N($C8)=0),"",$C8/100*N(INDEX('Pro قاعدة الأغذية'!$L$5:$L$604,$S8))) -> 1.2 | J8: =IF($S8="","",INDEX('Pro قاعدة الأغذية'!$E$5:$E$604,$S8)) -> نيء | S8: =IF(B8="","",IFERROR(MATCH(B8,'Pro قاعدة الأغذية'!$C$5:$C$604,0),"")) -> 78
D9: =IF(OR($S9="",N($C9)=0),"",$C9/100*N(INDEX('Pro قاعدة الأغذية'!$F$5:$F$604,$S9))) | E9: =IF(OR($S9="",N($C9)=0),"",$C9/100*N(INDEX('Pro قاعدة الأغذية'!$G$5:$G$604,$S9))) | F9: =IF(OR($S9="",N($C9)=0),"",$C9/100*N(INDEX('Pro قاعدة الأغذية'!$H$5:$H$604,$S9))) | G9: =IF(OR($S9="",N($C9)=0),"",$C9/100*N(INDEX('Pro قاعدة الأغذية'!$I$5:$I$604,$S9))) | H9: =IF(OR($S9="",N($C9)=0),"",$C9/100*N(INDEX('Pro قاعدة الأغذية'!$J$5:$J$604,$S9))) | I9: =IF(OR($S9="",N($C9)=0),"",$C9/100*N(INDEX('Pro قاعدة الأغذية'!$L$5:$L$604,$S9))) | J9: =IF($S9="","",INDEX('Pro قاعدة الأغذية'!$E$5:$E$604,$S9)) | S9: =IF(B9="","",IFERROR(MATCH(B9,'Pro قاعدة الأغذية'!$C$5:$C$604,0),""))
D10: =IF(OR($S10="",N($C10)=0),"",$C10/100*N(INDEX('Pro قاعدة الأغذية'!$F$5:$F$604,$S10))) | E10: =IF(OR($S10="",N($C10)=0),"",$C10/100*N(INDEX('Pro قاعدة الأغذية'!$G$5:$G$604,$S10))) | F10: =IF(OR($S10="",N($C10)=0),"",$C10/100*N(INDEX('Pro قاعدة الأغذية'!$H$5:$H$604,$S10))) | G10: =IF(OR($S10="",N($C10)=0),"",$C10/100*N(INDEX('Pro قاعدة الأغذية'!$I$5:$I$604,$S10))) | H10: =IF(OR($S10="",N($C10)=0),"",$C10/100*N(INDEX('Pro قاعدة الأغذية'!$J$5:$J$604,$S10))) | I10: =IF(OR($S10="",N($C10)=0),"",$C10/100*N(INDEX('Pro قاعدة الأغذية'!$L$5:$L$604,$S10))) | J10: =IF($S10="","",INDEX('Pro قاعدة الأغذية'!$E$5:$E$604,$S10)) | S10: =IF(B10="","",IFERROR(MATCH(B10,'Pro قاعدة الأغذية'!$C$5:$C$604,0),""))
D11: =IF(OR($S11="",N($C11)=0),"",$C11/100*N(INDEX('Pro قاعدة الأغذية'!$F$5:$F$604,$S11))) | E11: =IF(OR($S11="",N($C11)=0),"",$C11/100*N(INDEX('Pro قاعدة الأغذية'!$G$5:$G$604,$S11))) | F11: =IF(OR($S11="",N($C11)=0),"",$C11/100*N(INDEX('Pro قاعدة الأغذية'!$H$5:$H$604,$S11))) | G11: =IF(OR($S11="",N($C11)=0),"",$C11/100*N(INDEX('Pro قاعدة الأغذية'!$I$5:$I$604,$S11))) | H11: =IF(OR($S11="",N($C11)=0),"",$C11/100*N(INDEX('Pro قاعدة الأغذية'!$J$5:$J$604,$S11))) | I11: =IF(OR($S11="",N($C11)=0),"",$C11/100*N(INDEX('Pro قاعدة الأغذية'!$L$5:$L$604,$S11))) | J11: =IF($S11="","",INDEX('Pro قاعدة الأغذية'!$E$5:$E$604,$S11)) | S11: =IF(B11="","",IFERROR(MATCH(B11,'Pro قاعدة الأغذية'!$C$5:$C$604,0),""))
B12: مجموع الوجبة | C12: =SUM(C6:C11) -> 310 | D12: =SUM(D6:D11) -> 602.9 | E12: =SUM(E6:E11) -> 25.788 | F12: =SUM(F6:F11) -> 89.41 | G12: =SUM(G6:G11) -> 16.864 | H12: =SUM(H6:H11) -> 12.21 | I12: =SUM(I6:I11) -> 130.6 | K12: =IF(AND(('Pro إعدادات'!$C$33="نعم"),IF($T$4=1,'Pro إعدادات'!$G$39,'Pro إعدادات'!$D$39)>0),'Pro ملف الرياضي'!$H$23*IF($T$4=1,'Pro إعدادات'!$G$33,'Pro إعدادات'!$D$33)/IF($T$4=1,'Pro إعدادات'!$G$39,'Pro إعدادات'!$D$39),0) -> 28.8 | L12: =IF(AND(('Pro إعدادات'!$C$33="نعم"),IF($T$4=1,'Pro إعدادات'!$H$39,'Pro إعدادات'!$E$39)>0),'Pro ملف الرياضي'!$I$23*IF($T$4=1,'Pro إعدادات'!$H$33,'Pro إعدادات'!$E$33)/IF($T$4=1,'Pro إعدادات'!$H$39,'Pro إعدادات'!$E$39),0) -> 96 | M12: =IF(AND(('Pro إعدادات'!$C$33="نعم"),IF($T$4=1,'Pro إعدادات'!$I$39,'Pro إعدادات'!$F$39)>0),'Pro ملف الرياضي'!$J$23*IF($T$4=1,'Pro إعدادات'!$I$33,'Pro إعدادات'!$F$33)/IF($T$4=1,'Pro إعدادات'!$I$39,'Pro إعدادات'!$F$39),0) -> 18 | N12: =4*K12+4*L12+9*M12 -> 661.2 | O12: =E12-K12 -> -3.012 | P12: =F12-L12 -> -6.59 | Q12: =G12-M12 -> -1.136
A13: ='Pro إعدادات'!A34&" ("&'Pro إعدادات'!B34&")" -> سناك 1 / قبل التدريب (10:30) | B13: خبز بيتا (عربي) أبيض | C13: 100 | D13: =IF(OR($S13="",N($C13)=0),"",$C13/100*N(INDEX('Pro قاعدة الأغذية'!$F$5:$F$604,$S13))) -> 275 | E13: =IF(OR($S13="",N($C13)=0),"",$C13/100*N(INDEX('Pro قاعدة الأغذية'!$G$5:$G$604,$S13))) -> 9.1 | F13: =IF(OR($S13="",N($C13)=0),"",$C13/100*N(INDEX('Pro قاعدة الأغذية'!$H$5:$H$604,$S13))) -> 55.7 | G13: =IF(OR($S13="",N($C13)=0),"",$C13/100*N(INDEX('Pro قاعدة الأغذية'!$I$5:$I$604,$S13))) -> 1.2 | H13: =IF(OR($S13="",N($C13)=0),"",$C13/100*N(INDEX('Pro قاعدة الأغذية'!$J$5:$J$604,$S13))) -> 2.2 | I13: =IF(OR($S13="",N($C13)=0),"",$C13/100*N(INDEX('Pro قاعدة الأغذية'!$L$5:$L$604,$S13))) -> 536 | J13: =IF($S13="","",INDEX('Pro قاعدة الأغذية'!$E$5:$E$604,$S13)) -> غير محدد | S13: =IF(B13="","",IFERROR(MATCH(B13,'Pro قاعدة الأغذية'!$C$5:$C$604,0),"")) -> 16
B14: تمر مجدول | C14: 24 | D14: =IF(OR($S14="",N($C14)=0),"",$C14/100*N(INDEX('Pro قاعدة الأغذية'!$F$5:$F$604,$S14))) -> 66.48 | E14: =IF(OR($S14="",N($C14)=0),"",$C14/100*N(INDEX('Pro قاعدة الأغذية'!$G$5:$G$604,$S14))) -> 0.4344 | F14: =IF(OR($S14="",N($C14)=0),"",$C14/100*N(INDEX('Pro قاعدة الأغذية'!$H$5:$H$604,$S14))) -> 18 | G14: =IF(OR($S14="",N($C14)=0),"",$C14/100*N(INDEX('Pro قاعدة الأغذية'!$I$5:$I$604,$S14))) -> 0.036 | H14: =IF(OR($S14="",N($C14)=0),"",$C14/100*N(INDEX('Pro قاعدة الأغذية'!$J$5:$J$604,$S14))) -> 1.608 | I14: =IF(OR($S14="",N($C14)=0),"",$C14/100*N(INDEX('Pro قاعدة الأغذية'!$L$5:$L$604,$S14))) -> 0.24 | J14: =IF($S14="","",INDEX('Pro قاعدة الأغذية'!$E$5:$E$604,$S14)) -> غير محدد | S14: =IF(B14="","",IFERROR(MATCH(B14,'Pro قاعدة الأغذية'!$C$5:$C$604,0),"")) -> 81
B15: زبادي يوناني خالي الدسم | C15: 100 | D15: =IF(OR($S15="",N($C15)=0),"",$C15/100*N(INDEX('Pro قاعدة الأغذية'!$F$5:$F$604,$S15))) -> 59 | E15: =IF(OR($S15="",N($C15)=0),"",$C15/100*N(INDEX('Pro قاعدة الأغذية'!$G$5:$G$604,$S15))) -> 10.2 | F15: =IF(OR($S15="",N($C15)=0),"",$C15/100*N(INDEX('Pro قاعدة الأغذية'!$H$5:$H$604,$S15))) -> 3.6 | G15: =IF(OR($S15="",N($C15)=0),"",$C15/100*N(INDEX('Pro قاعدة الأغذية'!$I$5:$I$604,$S15))) -> 0.39 | H15: =IF(OR($S15="",N($C15)=0),"",$C15/100*N(INDEX('Pro قاعدة الأغذية'!$J$5:$J$604,$S15))) -> 0 | I15: =IF(OR($S15="",N($C15)=0),"",$C15/100*N(INDEX('Pro قاعدة الأغذية'!$L$5:$L$604,$S15))) -> 36 | J15: =IF($S15="","",INDEX('Pro قاعدة الأغذية'!$E$5:$E$604,$S15)) -> غير محدد | S15: =IF(B15="","",IFERROR(MATCH(B15,'Pro قاعدة الأغذية'!$C$5:$C$604,0),"")) -> 59
D16: =IF(OR($S16="",N($C16)=0),"",$C16/100*N(INDEX('Pro قاعدة الأغذية'!$F$5:$F$604,$S16))) | E16: =IF(OR($S16="",N($C16)=0),"",$C16/100*N(INDEX('Pro قاعدة الأغذية'!$G$5:$G$604,$S16))) | F16: =IF(OR($S16="",N($C16)=0),"",$C16/100*N(INDEX('Pro قاعدة الأغذية'!$H$5:$H$604,$S16))) | G16: =IF(OR($S16="",N($C16)=0),"",$C16/100*N(INDEX('Pro قاعدة الأغذية'!$I$5:$I$604,$S16))) | H16: =IF(OR($S16="",N($C16)=0),"",$C16/100*N(INDEX('Pro قاعدة الأغذية'!$J$5:$J$604,$S16))) | I16: =IF(OR($S16="",N($C16)=0),"",$C16/100*N(INDEX('Pro قاعدة الأغذية'!$L$5:$L$604,$S16))) | J16: =IF($S16="","",INDEX('Pro قاعدة الأغذية'!$E$5:$E$604,$S16)) | S16: =IF(B16="","",IFERROR(MATCH(B16,'Pro قاعدة الأغذية'!$C$5:$C$604,0),""))
D17: =IF(OR($S17="",N($C17)=0),"",$C17/100*N(INDEX('Pro قاعدة الأغذية'!$F$5:$F$604,$S17))) | E17: =IF(OR($S17="",N($C17)=0),"",$C17/100*N(INDEX('Pro قاعدة الأغذية'!$G$5:$G$604,$S17))) | F17: =IF(OR($S17="",N($C17)=0),"",$C17/100*N(INDEX('Pro قاعدة الأغذية'!$H$5:$H$604,$S17))) | G17: =IF(OR($S17="",N($C17)=0),"",$C17/100*N(INDEX('Pro قاعدة الأغذية'!$I$5:$I$604,$S17))) | H17: =IF(OR($S17="",N($C17)=0),"",$C17/100*N(INDEX('Pro قاعدة الأغذية'!$J$5:$J$604,$S17))) | I17: =IF(OR($S17="",N($C17)=0),"",$C17/100*N(INDEX('Pro قاعدة الأغذية'!$L$5:$L$604,$S17))) | J17: =IF($S17="","",INDEX('Pro قاعدة الأغذية'!$E$5:$E$604,$S17)) | S17: =IF(B17="","",IFERROR(MATCH(B17,'Pro قاعدة الأغذية'!$C$5:$C$604,0),""))
D18: =IF(OR($S18="",N($C18)=0),"",$C18/100*N(INDEX('Pro قاعدة الأغذية'!$F$5:$F$604,$S18))) | E18: =IF(OR($S18="",N($C18)=0),"",$C18/100*N(INDEX('Pro قاعدة الأغذية'!$G$5:$G$604,$S18))) | F18: =IF(OR($S18="",N($C18)=0),"",$C18/100*N(INDEX('Pro قاعدة الأغذية'!$H$5:$H$604,$S18))) | G18: =IF(OR($S18="",N($C18)=0),"",$C18/100*N(INDEX('Pro قاعدة الأغذية'!$I$5:$I$604,$S18))) | H18: =IF(OR($S18="",N($C18)=0),"",$C18/100*N(INDEX('Pro قاعدة الأغذية'!$J$5:$J$604,$S18))) | I18: =IF(OR($S18="",N($C18)=0),"",$C18/100*N(INDEX('Pro قاعدة الأغذية'!$L$5:$L$604,$S18))) | J18: =IF($S18="","",INDEX('Pro قاعدة الأغذية'!$E$5:$E$604,$S18)) | S18: =IF(B18="","",IFERROR(MATCH(B18,'Pro قاعدة الأغذية'!$C$5:$C$604,0),""))
B19: مجموع الوجبة | C19: =SUM(C13:C18) -> 224 | D19: =SUM(D13:D18) -> 400.48 | E19: =SUM(E13:E18) -> 19.7344 | F19: =SUM(F13:F18) -> 77.3 | G19: =SUM(G13:G18) -> 1.626 | H19: =SUM(H13:H18) -> 3.808 | I19: =SUM(I13:I18) -> 572.24 | K19: =IF(AND(('Pro إعدادات'!$C$34="نعم"),IF($T$4=1,'Pro إعدادات'!$G$39,'Pro إعدادات'!$D$39)>0),'Pro ملف الرياضي'!$H$23*IF($T$4=1,'Pro إعدادات'!$G$34,'Pro إعدادات'!$D$34)/IF($T$4=1,'Pro إعدادات'!$G$39,'Pro إعدادات'!$D$39),0) -> 14.4 | L19: =IF(AND(('Pro إعدادات'!$C$34="نعم"),IF($T$4=1,'Pro إعدادات'!$H$39,'Pro إعدادات'!$E$39)>0),'Pro ملف الرياضي'!$I$23*IF($T$4=1,'Pro إعدادات'!$H$34,'Pro إعدادات'!$E$34)/IF($T$4=1,'Pro إعدادات'!$H$39,'Pro إعدادات'!$E$39),0) -> 72 | M19: =IF(AND(('Pro إعدادات'!$C$34="نعم"),IF($T$4=1,'Pro إعدادات'!$I$39,'Pro إعدادات'!$F$39)>0),'Pro ملف الرياضي'!$J$23*IF($T$4=1,'Pro إعدادات'!$I$34,'Pro إعدادات'!$F$34)/IF($T$4=1,'Pro إعدادات'!$I$39,'Pro إعدادات'!$F$39),0) -> 3.6 | N19: =4*K19+4*L19+9*M19 -> 378 | O19: =E19-K19 -> 5.3344 | P19: =F19-L19 -> 5.3 | Q19: =G19-M19 -> -1.974
A20: ='Pro إعدادات'!A35&" ("&'Pro إعدادات'!B35&")" -> الغداء (13:30) | B20: أرز أبيض مطبوخ | C20: 400 | D20: =IF(OR($S20="",N($C20)=0),"",$C20/100*N(INDEX('Pro قاعدة الأغذية'!$F$5:$F$604,$S20))) -> 520 | E20: =IF(OR($S20="",N($C20)=0),"",$C20/100*N(INDEX('Pro قاعدة الأغذية'!$G$5:$G$604,$S20))) -> 10.76 | F20: =IF(OR($S20="",N($C20)=0),"",$C20/100*N(INDEX('Pro قاعدة الأغذية'!$H$5:$H$604,$S20))) -> 112.8 | G20: =IF(OR($S20="",N($C20)=0),"",$C20/100*N(INDEX('Pro قاعدة الأغذية'!$I$5:$I$604,$S20))) -> 1.12 | H20: =IF(OR($S20="",N($C20)=0),"",$C20/100*N(INDEX('Pro قاعدة الأغذية'!$J$5:$J$604,$S20))) -> 1.6 | I20: =IF(OR($S20="",N($C20)=0),"",$C20/100*N(INDEX('Pro قاعدة الأغذية'!$L$5:$L$604,$S20))) -> 4 | J20: =IF($S20="","",INDEX('Pro قاعدة الأغذية'!$E$5:$E$604,$S20)) -> مطبوخ | S20: =IF(B20="","",IFERROR(MATCH(B20,'Pro قاعدة الأغذية'!$C$5:$C$604,0),"")) -> 1
B21: صدر دجاج بلا جلد مشوي | C21: 100 | D21: =IF(OR($S21="",N($C21)=0),"",$C21/100*N(INDEX('Pro قاعدة الأغذية'!$F$5:$F$604,$S21))) -> 165 | E21: =IF(OR($S21="",N($C21)=0),"",$C21/100*N(INDEX('Pro قاعدة الأغذية'!$G$5:$G$604,$S21))) -> 31 | F21: =IF(OR($S21="",N($C21)=0),"",$C21/100*N(INDEX('Pro قاعدة الأغذية'!$H$5:$H$604,$S21))) -> 0 | G21: =IF(OR($S21="",N($C21)=0),"",$C21/100*N(INDEX('Pro قاعدة الأغذية'!$I$5:$I$604,$S21))) -> 3.57 | H21: =IF(OR($S21="",N($C21)=0),"",$C21/100*N(INDEX('Pro قاعدة الأغذية'!$J$5:$J$604,$S21))) -> 0 | I21: =IF(OR($S21="",N($C21)=0),"",$C21/100*N(INDEX('Pro قاعدة الأغذية'!$L$5:$L$604,$S21))) -> 74 | J21: =IF($S21="","",INDEX('Pro قاعدة الأغذية'!$E$5:$E$604,$S21)) -> مطبوخ | S21: =IF(B21="","",IFERROR(MATCH(B21,'Pro قاعدة الأغذية'!$C$5:$C$604,0),"")) -> 35
B22: بروكلي مسلوق | C22: 100 | D22: =IF(OR($S22="",N($C22)=0),"",$C22/100*N(INDEX('Pro قاعدة الأغذية'!$F$5:$F$604,$S22))) -> 35 | E22: =IF(OR($S22="",N($C22)=0),"",$C22/100*N(INDEX('Pro قاعدة الأغذية'!$G$5:$G$604,$S22))) -> 2.38 | F22: =IF(OR($S22="",N($C22)=0),"",$C22/100*N(INDEX('Pro قاعدة الأغذية'!$H$5:$H$604,$S22))) -> 7.18 | G22: =IF(OR($S22="",N($C22)=0),"",$C22/100*N(INDEX('Pro قاعدة الأغذية'!$I$5:$I$604,$S22))) -> 0.41 | H22: =IF(OR($S22="",N($C22)=0),"",$C22/100*N(INDEX('Pro قاعدة الأغذية'!$J$5:$J$604,$S22))) -> 3.3 | I22: =IF(OR($S22="",N($C22)=0),"",$C22/100*N(INDEX('Pro قاعدة الأغذية'!$L$5:$L$604,$S22))) -> 41 | J22: =IF($S22="","",INDEX('Pro قاعدة الأغذية'!$E$5:$E$604,$S22)) -> مطبوخ | S22: =IF(B22="","",IFERROR(MATCH(B22,'Pro قاعدة الأغذية'!$C$5:$C$604,0),"")) -> 107
B23: زيت زيتون | C23: 15 | D23: =IF(OR($S23="",N($C23)=0),"",$C23/100*N(INDEX('Pro قاعدة الأغذية'!$F$5:$F$604,$S23))) -> 132.6 | E23: =IF(OR($S23="",N($C23)=0),"",$C23/100*N(INDEX('Pro قاعدة الأغذية'!$G$5:$G$604,$S23))) -> 0 | F23: =IF(OR($S23="",N($C23)=0),"",$C23/100*N(INDEX('Pro قاعدة الأغذية'!$H$5:$H$604,$S23))) -> 0 | G23: =IF(OR($S23="",N($C23)=0),"",$C23/100*N(INDEX('Pro قاعدة الأغذية'!$I$5:$I$604,$S23))) -> 15 | H23: =IF(OR($S23="",N($C23)=0),"",$C23/100*N(INDEX('Pro قاعدة الأغذية'!$J$5:$J$604,$S23))) -> 0 | I23: =IF(OR($S23="",N($C23)=0),"",$C23/100*N(INDEX('Pro قاعدة الأغذية'!$L$5:$L$604,$S23))) -> 0.3 | J23: =IF($S23="","",INDEX('Pro قاعدة الأغذية'!$E$5:$E$604,$S23)) -> غير محدد | S23: =IF(B23="","",IFERROR(MATCH(B23,'Pro قاعدة الأغذية'!$C$5:$C$604,0),"")) -> 63
D24: =IF(OR($S24="",N($C24)=0),"",$C24/100*N(INDEX('Pro قاعدة الأغذية'!$F$5:$F$604,$S24))) | E24: =IF(OR($S24="",N($C24)=0),"",$C24/100*N(INDEX('Pro قاعدة الأغذية'!$G$5:$G$604,$S24))) | F24: =IF(OR($S24="",N($C24)=0),"",$C24/100*N(INDEX('Pro قاعدة الأغذية'!$H$5:$H$604,$S24))) | G24: =IF(OR($S24="",N($C24)=0),"",$C24/100*N(INDEX('Pro قاعدة الأغذية'!$I$5:$I$604,$S24))) | H24: =IF(OR($S24="",N($C24)=0),"",$C24/100*N(INDEX('Pro قاعدة الأغذية'!$J$5:$J$604,$S24))) | I24: =IF(OR($S24="",N($C24)=0),"",$C24/100*N(INDEX('Pro قاعدة الأغذية'!$L$5:$L$604,$S24))) | J24: =IF($S24="","",INDEX('Pro قاعدة الأغذية'!$E$5:$E$604,$S24)) | S24: =IF(B24="","",IFERROR(MATCH(B24,'Pro قاعدة الأغذية'!$C$5:$C$604,0),""))
D25: =IF(OR($S25="",N($C25)=0),"",$C25/100*N(INDEX('Pro قاعدة الأغذية'!$F$5:$F$604,$S25))) | E25: =IF(OR($S25="",N($C25)=0),"",$C25/100*N(INDEX('Pro قاعدة الأغذية'!$G$5:$G$604,$S25))) | F25: =IF(OR($S25="",N($C25)=0),"",$C25/100*N(INDEX('Pro قاعدة الأغذية'!$H$5:$H$604,$S25))) | G25: =IF(OR($S25="",N($C25)=0),"",$C25/100*N(INDEX('Pro قاعدة الأغذية'!$I$5:$I$604,$S25))) | H25: =IF(OR($S25="",N($C25)=0),"",$C25/100*N(INDEX('Pro قاعدة الأغذية'!$J$5:$J$604,$S25))) | I25: =IF(OR($S25="",N($C25)=0),"",$C25/100*N(INDEX('Pro قاعدة الأغذية'!$L$5:$L$604,$S25))) | J25: =IF($S25="","",INDEX('Pro قاعدة الأغذية'!$E$5:$E$604,$S25)) | S25: =IF(B25="","",IFERROR(MATCH(B25,'Pro قاعدة الأغذية'!$C$5:$C$604,0),""))
B26: مجموع الوجبة | C26: =SUM(C20:C25) -> 615 | D26: =SUM(D20:D25) -> 852.6 | E26: =SUM(E20:E25) -> 44.14 | F26: =SUM(F20:F25) -> 119.98 | G26: =SUM(G20:G25) -> 20.1 | H26: =SUM(H20:H25) -> 4.9 | I26: =SUM(I20:I25) -> 119.3 | K26: =IF(AND(('Pro إعدادات'!$C$35="نعم"),IF($T$4=1,'Pro إعدادات'!$G$39,'Pro إعدادات'!$D$39)>0),'Pro ملف الرياضي'!$H$23*IF($T$4=1,'Pro إعدادات'!$G$35,'Pro إعدادات'!$D$35)/IF($T$4=1,'Pro إعدادات'!$G$39,'Pro إعدادات'!$D$39),0) -> 36 | L26: =IF(AND(('Pro إعدادات'!$C$35="نعم"),IF($T$4=1,'Pro إعدادات'!$H$39,'Pro إعدادات'!$E$39)>0),'Pro ملف الرياضي'!$I$23*IF($T$4=1,'Pro إعدادات'!$H$35,'Pro إعدادات'!$E$35)/IF($T$4=1,'Pro إعدادات'!$H$39,'Pro إعدادات'!$E$39),0) -> 120 | M26: =IF(AND(('Pro إعدادات'!$C$35="نعم"),IF($T$4=1,'Pro إعدادات'!$I$39,'Pro إعدادات'!$F$39)>0),'Pro ملف الرياضي'!$J$23*IF($T$4=1,'Pro إعدادات'!$I$35,'Pro إعدادات'!$F$35)/IF($T$4=1,'Pro إعدادات'!$I$39,'Pro إعدادات'!$F$39),0) -> 21.6 | N26: =4*K26+4*L26+9*M26 -> 818.4 | O26: =E26-K26 -> 8.14 | P26: =F26-L26 -> -0.02 | Q26: =G26-M26 -> -1.5
A27: ='Pro إعدادات'!A36&" ("&'Pro إعدادات'!B36&")" -> سناك 2 / بعد التدريب (16:30) | B27: بروتين مصل اللبن (بودرة) | C27: 35 | D27: =IF(OR($S27="",N($C27)=0),"",$C27/100*N(INDEX('Pro قاعدة الأغذية'!$F$5:$F$604,$S27))) -> 123.2 | E27: =IF(OR($S27="",N($C27)=0),"",$C27/100*N(INDEX('Pro قاعدة الأغذية'!$G$5:$G$604,$S27))) -> 27.335 | F27: =IF(OR($S27="",N($C27)=0),"",$C27/100*N(INDEX('Pro قاعدة الأغذية'!$H$5:$H$604,$S27))) -> 2.1875 | G27: =IF(OR($S27="",N($C27)=0),"",$C27/100*N(INDEX('Pro قاعدة الأغذية'!$I$5:$I$604,$S27))) -> 0.546 | H27: =IF(OR($S27="",N($C27)=0),"",$C27/100*N(INDEX('Pro قاعدة الأغذية'!$J$5:$J$604,$S27))) -> 1.085 | I27: =IF(OR($S27="",N($C27)=0),"",$C27/100*N(INDEX('Pro قاعدة الأغذية'!$L$5:$L$604,$S27))) -> 54.6 | J27: =IF($S27="","",INDEX('Pro قاعدة الأغذية'!$E$5:$E$604,$S27)) -> غير محدد | S27: =IF(B27="","",IFERROR(MATCH(B27,'Pro قاعدة الأغذية'!$C$5:$C$604,0),"")) -> 52
B28: موز | C28: 120 | D28: =IF(OR($S28="",N($C28)=0),"",$C28/100*N(INDEX('Pro قاعدة الأغذية'!$F$5:$F$604,$S28))) -> 106.8 | E28: =IF(OR($S28="",N($C28)=0),"",$C28/100*N(INDEX('Pro قاعدة الأغذية'!$G$5:$G$604,$S28))) -> 1.308 | F28: =IF(OR($S28="",N($C28)=0),"",$C28/100*N(INDEX('Pro قاعدة الأغذية'!$H$5:$H$604,$S28))) -> 27.36 | G28: =IF(OR($S28="",N($C28)=0),"",$C28/100*N(INDEX('Pro قاعدة الأغذية'!$I$5:$I$604,$S28))) -> 0.396 | H28: =IF(OR($S28="",N($C28)=0),"",$C28/100*N(INDEX('Pro قاعدة الأغذية'!$J$5:$J$604,$S28))) -> 3.12 | I28: =IF(OR($S28="",N($C28)=0),"",$C28/100*N(INDEX('Pro قاعدة الأغذية'!$L$5:$L$604,$S28))) -> 1.2 | J28: =IF($S28="","",INDEX('Pro قاعدة الأغذية'!$E$5:$E$604,$S28)) -> نيء | S28: =IF(B28="","",IFERROR(MATCH(B28,'Pro قاعدة الأغذية'!$C$5:$C$604,0),"")) -> 78
B29: تمر مجدول | C29: 90 | D29: =IF(OR($S29="",N($C29)=0),"",$C29/100*N(INDEX('Pro قاعدة الأغذية'!$F$5:$F$604,$S29))) -> 249.3 | E29: =IF(OR($S29="",N($C29)=0),"",$C29/100*N(INDEX('Pro قاعدة الأغذية'!$G$5:$G$604,$S29))) -> 1.629 | F29: =IF(OR($S29="",N($C29)=0),"",$C29/100*N(INDEX('Pro قاعدة الأغذية'!$H$5:$H$604,$S29))) -> 67.5 | G29: =IF(OR($S29="",N($C29)=0),"",$C29/100*N(INDEX('Pro قاعدة الأغذية'!$I$5:$I$604,$S29))) -> 0.135 | H29: =IF(OR($S29="",N($C29)=0),"",$C29/100*N(INDEX('Pro قاعدة الأغذية'!$J$5:$J$604,$S29))) -> 6.03 | I29: =IF(OR($S29="",N($C29)=0),"",$C29/100*N(INDEX('Pro قاعدة الأغذية'!$L$5:$L$604,$S29))) -> 0.9 | J29: =IF($S29="","",INDEX('Pro قاعدة الأغذية'!$E$5:$E$604,$S29)) -> غير محدد | S29: =IF(B29="","",IFERROR(MATCH(B29,'Pro قاعدة الأغذية'!$C$5:$C$604,0),"")) -> 81
D30: =IF(OR($S30="",N($C30)=0),"",$C30/100*N(INDEX('Pro قاعدة الأغذية'!$F$5:$F$604,$S30))) | E30: =IF(OR($S30="",N($C30)=0),"",$C30/100*N(INDEX('Pro قاعدة الأغذية'!$G$5:$G$604,$S30))) | F30: =IF(OR($S30="",N($C30)=0),"",$C30/100*N(INDEX('Pro قاعدة الأغذية'!$H$5:$H$604,$S30))) | G30: =IF(OR($S30="",N($C30)=0),"",$C30/100*N(INDEX('Pro قاعدة الأغذية'!$I$5:$I$604,$S30))) | H30: =IF(OR($S30="",N($C30)=0),"",$C30/100*N(INDEX('Pro قاعدة الأغذية'!$J$5:$J$604,$S30))) | I30: =IF(OR($S30="",N($C30)=0),"",$C30/100*N(INDEX('Pro قاعدة الأغذية'!$L$5:$L$604,$S30))) | J30: =IF($S30="","",INDEX('Pro قاعدة الأغذية'!$E$5:$E$604,$S30)) | S30: =IF(B30="","",IFERROR(MATCH(B30,'Pro قاعدة الأغذية'!$C$5:$C$604,0),""))
D31: =IF(OR($S31="",N($C31)=0),"",$C31/100*N(INDEX('Pro قاعدة الأغذية'!$F$5:$F$604,$S31))) | E31: =IF(OR($S31="",N($C31)=0),"",$C31/100*N(INDEX('Pro قاعدة الأغذية'!$G$5:$G$604,$S31))) | F31: =IF(OR($S31="",N($C31)=0),"",$C31/100*N(INDEX('Pro قاعدة الأغذية'!$H$5:$H$604,$S31))) | G31: =IF(OR($S31="",N($C31)=0),"",$C31/100*N(INDEX('Pro قاعدة الأغذية'!$I$5:$I$604,$S31))) | H31: =IF(OR($S31="",N($C31)=0),"",$C31/100*N(INDEX('Pro قاعدة الأغذية'!$J$5:$J$604,$S31))) | I31: =IF(OR($S31="",N($C31)=0),"",$C31/100*N(INDEX('Pro قاعدة الأغذية'!$L$5:$L$604,$S31))) | J31: =IF($S31="","",INDEX('Pro قاعدة الأغذية'!$E$5:$E$604,$S31)) | S31: =IF(B31="","",IFERROR(MATCH(B31,'Pro قاعدة الأغذية'!$C$5:$C$604,0),""))
D32: =IF(OR($S32="",N($C32)=0),"",$C32/100*N(INDEX('Pro قاعدة الأغذية'!$F$5:$F$604,$S32))) | E32: =IF(OR($S32="",N($C32)=0),"",$C32/100*N(INDEX('Pro قاعدة الأغذية'!$G$5:$G$604,$S32))) | F32: =IF(OR($S32="",N($C32)=0),"",$C32/100*N(INDEX('Pro قاعدة الأغذية'!$H$5:$H$604,$S32))) | G32: =IF(OR($S32="",N($C32)=0),"",$C32/100*N(INDEX('Pro قاعدة الأغذية'!$I$5:$I$604,$S32))) | H32: =IF(OR($S32="",N($C32)=0),"",$C32/100*N(INDEX('Pro قاعدة الأغذية'!$J$5:$J$604,$S32))) | I32: =IF(OR($S32="",N($C32)=0),"",$C32/100*N(INDEX('Pro قاعدة الأغذية'!$L$5:$L$604,$S32))) | J32: =IF($S32="","",INDEX('Pro قاعدة الأغذية'!$E$5:$E$604,$S32)) | S32: =IF(B32="","",IFERROR(MATCH(B32,'Pro قاعدة الأغذية'!$C$5:$C$604,0),""))
B33: مجموع الوجبة | C33: =SUM(C27:C32) -> 245 | D33: =SUM(D27:D32) -> 479.3 | E33: =SUM(E27:E32) -> 30.272 | F33: =SUM(F27:F32) -> 97.0475 | G33: =SUM(G27:G32) -> 1.077 | H33: =SUM(H27:H32) -> 10.235 | I33: =SUM(I27:I32) -> 56.7 | K33: =IF(AND(('Pro إعدادات'!$C$36="نعم"),IF($T$4=1,'Pro إعدادات'!$G$39,'Pro إعدادات'!$D$39)>0),'Pro ملف الرياضي'!$H$23*IF($T$4=1,'Pro إعدادات'!$G$36,'Pro إعدادات'!$D$36)/IF($T$4=1,'Pro إعدادات'!$G$39,'Pro إعدادات'!$D$39),0) -> 28.8 | L33: =IF(AND(('Pro إعدادات'!$C$36="نعم"),IF($T$4=1,'Pro إعدادات'!$H$39,'Pro إعدادات'!$E$39)>0),'Pro ملف الرياضي'!$I$23*IF($T$4=1,'Pro إعدادات'!$H$36,'Pro إعدادات'!$E$36)/IF($T$4=1,'Pro إعدادات'!$H$39,'Pro إعدادات'!$E$39),0) -> 120 | M33: =IF(AND(('Pro إعدادات'!$C$36="نعم"),IF($T$4=1,'Pro إعدادات'!$I$39,'Pro إعدادات'!$F$39)>0),'Pro ملف الرياضي'!$J$23*IF($T$4=1,'Pro إعدادات'!$I$36,'Pro إعدادات'!$F$36)/IF($T$4=1,'Pro إعدادات'!$I$39,'Pro إعدادات'!$F$39),0) -> 7.2 | N33: =4*K33+4*L33+9*M33 -> 660 | O33: =E33-K33 -> 1.472 | P33: =F33-L33 -> -22.9525 | Q33: =G33-M33 -> -6.123
A34: ='Pro إعدادات'!A37&" ("&'Pro إعدادات'!B37&")" -> العشاء (20:00) | B34: بطاطا حلوة مشوية | C34: 300 | D34: =IF(OR($S34="",N($C34)=0),"",$C34/100*N(INDEX('Pro قاعدة الأغذية'!$F$5:$F$604,$S34))) -> 270 | E34: =IF(OR($S34="",N($C34)=0),"",$C34/100*N(INDEX('Pro قاعدة الأغذية'!$G$5:$G$604,$S34))) -> 6.03 | F34: =IF(OR($S34="",N($C34)=0),"",$C34/100*N(INDEX('Pro قاعدة الأغذية'!$H$5:$H$604,$S34))) -> 62.1 | G34: =IF(OR($S34="",N($C34)=0),"",$C34/100*N(INDEX('Pro قاعدة الأغذية'!$I$5:$I$604,$S34))) -> 0.45 | H34: =IF(OR($S34="",N($C34)=0),"",$C34/100*N(INDEX('Pro قاعدة الأغذية'!$J$5:$J$604,$S34))) -> 9.9 | I34: =IF(OR($S34="",N($C34)=0),"",$C34/100*N(INDEX('Pro قاعدة الأغذية'!$L$5:$L$604,$S34))) -> 108 | J34: =IF($S34="","",INDEX('Pro قاعدة الأغذية'!$E$5:$E$604,$S34)) -> مطبوخ | S34: =IF(B34="","",IFERROR(MATCH(B34,'Pro قاعدة الأغذية'!$C$5:$C$604,0),"")) -> 21
B35: سلمون أطلسي (مزارع) مطبوخ | C35: 120 | D35: =IF(OR($S35="",N($C35)=0),"",$C35/100*N(INDEX('Pro قاعدة الأغذية'!$F$5:$F$604,$S35))) -> 247.2 | E35: =IF(OR($S35="",N($C35)=0),"",$C35/100*N(INDEX('Pro قاعدة الأغذية'!$G$5:$G$604,$S35))) -> 26.52 | F35: =IF(OR($S35="",N($C35)=0),"",$C35/100*N(INDEX('Pro قاعدة الأغذية'!$H$5:$H$604,$S35))) -> 0 | G35: =IF(OR($S35="",N($C35)=0),"",$C35/100*N(INDEX('Pro قاعدة الأغذية'!$I$5:$I$604,$S35))) -> 14.88 | H35: =IF(OR($S35="",N($C35)=0),"",$C35/100*N(INDEX('Pro قاعدة الأغذية'!$J$5:$J$604,$S35))) -> 0 | I35: =IF(OR($S35="",N($C35)=0),"",$C35/100*N(INDEX('Pro قاعدة الأغذية'!$L$5:$L$604,$S35))) -> 73.2 | J35: =IF($S35="","",INDEX('Pro قاعدة الأغذية'!$E$5:$E$604,$S35)) -> مطبوخ | S35: =IF(B35="","",IFERROR(MATCH(B35,'Pro قاعدة الأغذية'!$C$5:$C$604,0),"")) -> 47
B36: خس روماني | C36: 80 | D36: =IF(OR($S36="",N($C36)=0),"",$C36/100*N(INDEX('Pro قاعدة الأغذية'!$F$5:$F$604,$S36))) -> 13.6 | E36: =IF(OR($S36="",N($C36)=0),"",$C36/100*N(INDEX('Pro قاعدة الأغذية'!$G$5:$G$604,$S36))) -> 0.984 | F36: =IF(OR($S36="",N($C36)=0),"",$C36/100*N(INDEX('Pro قاعدة الأغذية'!$H$5:$H$604,$S36))) -> 2.632 | G36: =IF(OR($S36="",N($C36)=0),"",$C36/100*N(INDEX('Pro قاعدة الأغذية'!$I$5:$I$604,$S36))) -> 0.24 | H36: =IF(OR($S36="",N($C36)=0),"",$C36/100*N(INDEX('Pro قاعدة الأغذية'!$J$5:$J$604,$S36))) -> 1.68 | I36: =IF(OR($S36="",N($C36)=0),"",$C36/100*N(INDEX('Pro قاعدة الأغذية'!$L$5:$L$604,$S36))) -> 6.4 | J36: =IF($S36="","",INDEX('Pro قاعدة الأغذية'!$E$5:$E$604,$S36)) -> نيء | S36: =IF(B36="","",IFERROR(MATCH(B36,'Pro قاعدة الأغذية'!$C$5:$C$604,0),"")) -> 102
B37: زيت زيتون | C37: 10 | D37: =IF(OR($S37="",N($C37)=0),"",$C37/100*N(INDEX('Pro قاعدة الأغذية'!$F$5:$F$604,$S37))) -> 88.4 | E37: =IF(OR($S37="",N($C37)=0),"",$C37/100*N(INDEX('Pro قاعدة الأغذية'!$G$5:$G$604,$S37))) -> 0 | F37: =IF(OR($S37="",N($C37)=0),"",$C37/100*N(INDEX('Pro قاعدة الأغذية'!$H$5:$H$604,$S37))) -> 0 | G37: =IF(OR($S37="",N($C37)=0),"",$C37/100*N(INDEX('Pro قاعدة الأغذية'!$I$5:$I$604,$S37))) -> 10 | H37: =IF(OR($S37="",N($C37)=0),"",$C37/100*N(INDEX('Pro قاعدة الأغذية'!$J$5:$J$604,$S37))) -> 0 | I37: =IF(OR($S37="",N($C37)=0),"",$C37/100*N(INDEX('Pro قاعدة الأغذية'!$L$5:$L$604,$S37))) -> 0.2 | J37: =IF($S37="","",INDEX('Pro قاعدة الأغذية'!$E$5:$E$604,$S37)) -> غير محدد | S37: =IF(B37="","",IFERROR(MATCH(B37,'Pro قاعدة الأغذية'!$C$5:$C$604,0),"")) -> 63
D38: =IF(OR($S38="",N($C38)=0),"",$C38/100*N(INDEX('Pro قاعدة الأغذية'!$F$5:$F$604,$S38))) | E38: =IF(OR($S38="",N($C38)=0),"",$C38/100*N(INDEX('Pro قاعدة الأغذية'!$G$5:$G$604,$S38))) | F38: =IF(OR($S38="",N($C38)=0),"",$C38/100*N(INDEX('Pro قاعدة الأغذية'!$H$5:$H$604,$S38))) | G38: =IF(OR($S38="",N($C38)=0),"",$C38/100*N(INDEX('Pro قاعدة الأغذية'!$I$5:$I$604,$S38))) | H38: =IF(OR($S38="",N($C38)=0),"",$C38/100*N(INDEX('Pro قاعدة الأغذية'!$J$5:$J$604,$S38))) | I38: =IF(OR($S38="",N($C38)=0),"",$C38/100*N(INDEX('Pro قاعدة الأغذية'!$L$5:$L$604,$S38))) | J38: =IF($S38="","",INDEX('Pro قاعدة الأغذية'!$E$5:$E$604,$S38)) | S38: =IF(B38="","",IFERROR(MATCH(B38,'Pro قاعدة الأغذية'!$C$5:$C$604,0),""))
D39: =IF(OR($S39="",N($C39)=0),"",$C39/100*N(INDEX('Pro قاعدة الأغذية'!$F$5:$F$604,$S39))) | E39: =IF(OR($S39="",N($C39)=0),"",$C39/100*N(INDEX('Pro قاعدة الأغذية'!$G$5:$G$604,$S39))) | F39: =IF(OR($S39="",N($C39)=0),"",$C39/100*N(INDEX('Pro قاعدة الأغذية'!$H$5:$H$604,$S39))) | G39: =IF(OR($S39="",N($C39)=0),"",$C39/100*N(INDEX('Pro قاعدة الأغذية'!$I$5:$I$604,$S39))) | H39: =IF(OR($S39="",N($C39)=0),"",$C39/100*N(INDEX('Pro قاعدة الأغذية'!$J$5:$J$604,$S39))) | I39: =IF(OR($S39="",N($C39)=0),"",$C39/100*N(INDEX('Pro قاعدة الأغذية'!$L$5:$L$604,$S39))) | J39: =IF($S39="","",INDEX('Pro قاعدة الأغذية'!$E$5:$E$604,$S39)) | S39: =IF(B39="","",IFERROR(MATCH(B39,'Pro قاعدة الأغذية'!$C$5:$C$604,0),""))
B40: مجموع الوجبة | C40: =SUM(C34:C39) -> 510 | D40: =SUM(D34:D39) -> 619.2 | E40: =SUM(E34:E39) -> 33.534 | F40: =SUM(F34:F39) -> 64.732 | G40: =SUM(G34:G39) -> 25.57 | H40: =SUM(H34:H39) -> 11.58 | I40: =SUM(I34:I39) -> 187.8 | K40: =IF(AND(('Pro إعدادات'!$C$37="نعم"),IF($T$4=1,'Pro إعدادات'!$G$39,'Pro إعدادات'!$D$39)>0),'Pro ملف الرياضي'!$H$23*IF($T$4=1,'Pro إعدادات'!$G$37,'Pro إعدادات'!$D$37)/IF($T$4=1,'Pro إعدادات'!$G$39,'Pro إعدادات'!$D$39),0) -> 36 | L40: =IF(AND(('Pro إعدادات'!$C$37="نعم"),IF($T$4=1,'Pro إعدادات'!$H$39,'Pro إعدادات'!$E$39)>0),'Pro ملف الرياضي'!$I$23*IF($T$4=1,'Pro إعدادات'!$H$37,'Pro إعدادات'!$E$37)/IF($T$4=1,'Pro إعدادات'!$H$39,'Pro إعدادات'!$E$39),0) -> 72 | M40: =IF(AND(('Pro إعدادات'!$C$37="نعم"),IF($T$4=1,'Pro إعدادات'!$I$39,'Pro إعدادات'!$F$39)>0),'Pro ملف الرياضي'!$J$23*IF($T$4=1,'Pro إعدادات'!$I$37,'Pro إعدادات'!$F$37)/IF($T$4=1,'Pro إعدادات'!$I$39,'Pro إعدادات'!$F$39),0) -> 21.6 | N40: =4*K40+4*L40+9*M40 -> 626.4 | O40: =E40-K40 -> -2.466 | P40: =F40-L40 -> -7.268 | Q40: =G40-M40 -> 3.97
A41: ='Pro إعدادات'!A38&" ("&'Pro إعدادات'!B38&")" -> وجبة ليلية (22:30) | D41: =IF(OR($S41="",N($C41)=0),"",$C41/100*N(INDEX('Pro قاعدة الأغذية'!$F$5:$F$604,$S41))) | E41: =IF(OR($S41="",N($C41)=0),"",$C41/100*N(INDEX('Pro قاعدة الأغذية'!$G$5:$G$604,$S41))) | F41: =IF(OR($S41="",N($C41)=0),"",$C41/100*N(INDEX('Pro قاعدة الأغذية'!$H$5:$H$604,$S41))) | G41: =IF(OR($S41="",N($C41)=0),"",$C41/100*N(INDEX('Pro قاعدة الأغذية'!$I$5:$I$604,$S41))) | H41: =IF(OR($S41="",N($C41)=0),"",$C41/100*N(INDEX('Pro قاعدة الأغذية'!$J$5:$J$604,$S41))) | I41: =IF(OR($S41="",N($C41)=0),"",$C41/100*N(INDEX('Pro قاعدة الأغذية'!$L$5:$L$604,$S41))) | J41: =IF($S41="","",INDEX('Pro قاعدة الأغذية'!$E$5:$E$604,$S41)) | S41: =IF(B41="","",IFERROR(MATCH(B41,'Pro قاعدة الأغذية'!$C$5:$C$604,0),""))
...

Sheet Pro باني الوجبة
A1: Pro — باني الوجبة: يحسب الجرامات لتحقيق هدف بروتين/كارب/دهون
A2: اكتب هدف الوجبة بالجرام، واختر مصدر بروتين ومصدر كارب ومصدر دهون (ويمكن إضافة صنف ثابت بجرام معلوم)؛ يحل النظام معادلات الماكروز ويعرض الجرامات (مقرَّبة لأقرب 5 جم) والماكروز الناتج.
A4: هدف البروتين (جم) | B4: 40
A5: هدف الكارب (جم) | B5: 70
A6: هدف الدهون (جم) | B6: 15
A8: مصدر البروتين | B8: صدر دجاج بلا جلد مشوي
A9: مصدر الكارب | B9: أرز أبيض مطبوخ
A10: مصدر الدهون | B10: زيت زيتون
A11: صنف ثابت (اختياري) | B11: بروكلي مسلوق
A12: جرامات الصنف الثابت | B12: 100
B14: بروتين/جم | C14: كارب/جم | D14: دهون/جم
A15: =B8 -> صدر دجاج بلا جلد مشوي | B15: =IFERROR(INDEX('Pro قاعدة الأغذية'!$G$5:$G$604,MATCH(B8,'Pro قاعدة الأغذية'!$C$5:$C$604,0))/100,0) -> 0.31 | C15: =IFERROR(INDEX('Pro قاعدة الأغذية'!$H$5:$H$604,MATCH(B8,'Pro قاعدة الأغذية'!$C$5:$C$604,0))/100,0) -> 0 | D15: =IFERROR(INDEX('Pro قاعدة الأغذية'!$I$5:$I$604,MATCH(B8,'Pro قاعدة الأغذية'!$C$5:$C$604,0))/100,0) -> 0.0357
A16: =B9 -> أرز أبيض مطبوخ | B16: =IFERROR(INDEX('Pro قاعدة الأغذية'!$G$5:$G$604,MATCH(B9,'Pro قاعدة الأغذية'!$C$5:$C$604,0))/100,0) -> 0.0269 | C16: =IFERROR(INDEX('Pro قاعدة الأغذية'!$H$5:$H$604,MATCH(B9,'Pro قاعدة الأغذية'!$C$5:$C$604,0))/100,0) -> 0.282 | D16: =IFERROR(INDEX('Pro قاعدة الأغذية'!$I$5:$I$604,MATCH(B9,'Pro قاعدة الأغذية'!$C$5:$C$604,0))/100,0) -> 0.0028
A17: =B10 -> زيت زيتون | B17: =IFERROR(INDEX('Pro قاعدة الأغذية'!$G$5:$G$604,MATCH(B10,'Pro قاعدة الأغذية'!$C$5:$C$604,0))/100,0) -> 0 | C17: =IFERROR(INDEX('Pro قاعدة الأغذية'!$H$5:$H$604,MATCH(B10,'Pro قاعدة الأغذية'!$C$5:$C$604,0))/100,0) -> 0 | D17: =IFERROR(INDEX('Pro قاعدة الأغذية'!$I$5:$I$604,MATCH(B10,'Pro قاعدة الأغذية'!$C$5:$C$604,0))/100,0) -> 1
A18: =B11 -> بروكلي مسلوق | B18: =IFERROR(INDEX('Pro قاعدة الأغذية'!$G$5:$G$604,MATCH(B11,'Pro قاعدة الأغذية'!$C$5:$C$604,0))/100,0) -> 0.0238 | C18: =IFERROR(INDEX('Pro قاعدة الأغذية'!$H$5:$H$604,MATCH(B11,'Pro قاعدة الأغذية'!$C$5:$C$604,0))/100,0) -> 0.0718 | D18: =IFERROR(INDEX('Pro قاعدة الأغذية'!$I$5:$I$604,MATCH(B11,'Pro قاعدة الأغذية'!$C$5:$C$604,0))/100,0) -> 0.0041
B19: بروتين | C19: كارب | D19: دهون
A20: الهدف بعد خصم الصنف الثابت | B20: =B4-B12*B18 -> 37.62 | C20: =B5-B12*C18 -> 62.82 | D20: =B6-B12*D18 -> 14.59
A22: المحدد (det) | B22: =(B15*(C16*D17-C17*D16)-B16*(C15*D17-C17*D15)+B17*(C15*D16-C16*D15)) -> 0.08742
A23: محددات كرامر | B23: =(B20*(C16*D17-C17*D16)-B16*(C20*D17-C17*D20)+B17*(C20*D16-C16*D20)) -> 8.918982 | C23: =(B15*(C20*D17-C17*D20)-B20*(C15*D17-C17*D15)+B17*(C15*D20-C20*D15)) -> 19.4742 | D23: =(B15*(C16*D20-C20*D16)-B16*(C15*D20-C20*D15)+B20*(C15*D16-C16*D15)) -> 0.90252238
A25: النتيجة (جرام) | B25: مصدر البروتين | C25: مصدر الكارب | D25: مصدر الدهون | E25: الصنف الثابت
A26: الجرامات (مقرَّبة لأقرب 5) | B26: =IF(ABS($B$22)<0.0000001,"تعذّر الحل",IF(B23/$B$22<0,"سالب — بدّل الأصناف",MROUND(B23/$B$22,5))) -> 100 | C26: =IF(ABS($B$22)<0.0000001,"تعذّر الحل",IF(C23/$B$22<0,"سالب — بدّل الأصناف",MROUND(C23/$B$22,5))) -> 225 | D26: =IF(ABS($B$22)<0.0000001,"تعذّر الحل",IF(D23/$B$22<0,"سالب — بدّل الأصناف",MROUND(D23/$B$22,5))) -> 10 | E26: =B12 -> 100
A27: الأصناف | B27: =B8 -> صدر دجاج بلا جلد مشوي | C27: =B9 -> أرز أبيض مطبوخ | D27: =B10 -> زيت زيتون | E27: =B11 -> بروكلي مسلوق
A29: الماكروز الناتج | B29: بروتين | C29: كارب | D29: دهون | E29: kcal
A30: الناتج | B30: =N(B26)*B15+N(C26)*B16+N(D26)*B17+E26*B18 -> 39.4325 | C30: =N(B26)*C15+N(C26)*C16+N(D26)*C17+E26*C18 -> 70.63 | D30: =N(B26)*D15+N(C26)*D16+N(D26)*D17+E26*D18 -> 14.61 | E30: =4*B30+4*C30+9*D30 -> 571.74
A31: الفرق عن الهدف | B31: =B30-B4 -> -0.5675 | C31: =C30-B5 -> 0.63 | D31: =D30-B6 -> -0.39

Sheet Pro قاعدة الأغذية
A1: Pro — قاعدة الأغذية بالجرام (القيم لكل 100 جم) — المصدر: USDA FoodData Central
A2: القيم لكل 100 جم من الغذاء بحالته المذكورة (نيء/مطبوخ). أضف أصنافاً في الصفوف الفارغة (حتى 600 صنف) بنسخ صفوف من ملف Pro_Foods_Database.xlsx أو من ملصق المنتج. لا تحوّل بين النيء والمطبوخ دون معامل مُوثَّق.
A4: ID | B4: المجموعة | C4: الاسم | D4: الوصف (English) | E4: الحالة | F4: kcal | G4: بروتين g | H4: كربوهيدرات g | I4: دهون g | J4: ألياف g | K4: سكريات g | L4: صوديوم mg | M4: المصدر | N4: نشط
A5: P001 | B5: نشويات وحبوب | C5: أرز أبيض مطبوخ | D5: Rice, white, long-grain, regular, enriched, cooked | E5: مطبوخ | F5: 130 | G5: 2.69 | H5: 28.2 | I5: 0.28 | J5: 0.4 | K5: 0.05 | L5: 1 | M5: USDA SR Legacy 2018-04 (NDB 20045 / FDC 168878) | N5: نعم
A6: P002 | B6: نشويات وحبوب | C6: أرز أبيض نيء | D6: Rice, white, long-grain, regular, raw, enriched | E6: نيء | F6: 365 | G6: 7.13 | H6: 80 | I6: 0.66 | J6: 1.3 | K6: 0.12 | L6: 5 | M6: USDA SR Legacy 2018-04 (NDB 20044 / FDC 168877) | N6: نعم
A7: P003 | B7: نشويات وحبوب | C7: أرز بني مطبوخ | D7: Rice, brown, long-grain, cooked (Includes foods for USDA's Food Distribution Program) | E7: مطبوخ | F7: 123 | G7: 2.74 | H7: 25.6 | I7: 0.97 | J7: 1.6 | K7: 0.24 | L7: 4 | M7: USDA SR Legacy 2018-04 (NDB 20037 / FDC 169704) | N7: نعم
A8: P004 | B8: نشويات وحبوب | C8: أرز بني نيء | D8: Rice, brown, long-grain, raw (Includes foods for USDA's Food Distribution Program) | E8: نيء | F8: 367 | G8: 7.54 | H8: 76.2 | I8: 3.2 | J8: 3.6 | K8: 0.66 | L8: 5 | M8: USDA SR Legacy 2018-04 (NDB 20036 / FDC 169703) | N8: نعم
A9: P005 | B9: نشويات وحبوب | C9: معكرونة مطبوخة | D9: Pasta, cooked, enriched, without added salt | E9: مطبوخ | F9: 158 | G9: 5.8 | H9: 30.9 | I9: 0.93 | J9: 1.8 | K9: 0.56 | L9: 1 | M9: USDA SR Legacy 2018-04 (NDB 20121 / FDC 169737) | N9: نعم
A10: P006 | B10: نشويات وحبوب | C10: معكرونة جافة | D10: Pasta, dry, enriched | E10: مجفّف/جاف | F10: 371 | G10: 13 | H10: 74.7 | I10: 1.51 | J10: 3.2 | K10: 2.67 | L10: 6 | M10: USDA SR Legacy 2018-04 (NDB 20120 / FDC 169736) | N10: نعم
A11: P007 | B11: نشويات وحبوب | C11: معكرونة قمح كامل مطبوخة | D11: Pasta, whole-wheat, cooked (Includes foods for USDA's Food Distribution Program) | E11: مطبوخ | F11: 149 | G11: 5.99 | H11: 30.1 | I11: 1.71 | J11: 3.9 | K11: 0.75 | L11: 4 | M11: USDA SR Legacy 2018-04 (NDB 20125 / FDC 168910) | N11: نعم
A12: P008 | B12: نشويات وحبوب | C12: كسكس مطبوخ | D12: Couscous, cooked | E12: مطبوخ | F12: 112 | G12: 3.79 | H12: 23.2 | I12: 0.16 | J12: 1.4 | K12: 0.1 | L12: 5 | M12: USDA SR Legacy 2018-04 (NDB 20029 / FDC 169700) | N12: نعم
A13: P009 | B13: نشويات وحبوب | C13: برغل مطبوخ | D13: Bulgur, cooked | E13: مطبوخ | F13: 83 | G13: 3.08 | H13: 18.6 | I13: 0.24 | J13: 4.5 | K13: 0.1 | L13: 5 | M13: USDA SR Legacy 2018-04 (NDB 20013 / FDC 170287) | N13: نعم
A14: P010 | B14: نشويات وحبوب | C14: برغل جاف | D14: Bulgur, dry | E14: مجفّف/جاف | F14: 342 | G14: 12.3 | H14: 75.9 | I14: 1.33 | J14: 12.5 | K14: 0.41 | L14: 17 | M14: USDA SR Legacy 2018-04 (NDB 20012 / FDC 170688) | N14: نعم
A15: P011 | B15: نشويات وحبوب | C15: كينوا مطبوخة | D15: Quinoa, cooked | E15: مطبوخ | F15: 120 | G15: 4.4 | H15: 21.3 | I15: 1.92 | J15: 2.8 | K15: 0.87 | L15: 7 | M15: USDA SR Legacy 2018-04 (NDB 20137 / FDC 168917) | N15: نعم
A16: P012 | B16: نشويات وحبوب | C16: شوفان جاف | D16: Cereals, oats, regular and quick, not fortified, dry | E16: مجفّف/جاف | F16: 379 | G16: 13.2 | H16: 67.7 | I16: 6.52 | J16: 10.1 | K16: 0.99 | L16: 6 | M16: USDA SR Legacy 2018-04 (NDB 8120 / FDC 173904) | N16: نعم
... A21: P017 | B21: نشويات وحبوب | C21: خبز بيتا (عربي) قمح كامل | D21: Bread, pita, whole-wheat | E21: غير محدد | F21: 262 | G21: 9.8 | H21: 55.9 | I21: 1.71 | J21: 6.1 | K21: 2.87 | L21: 421 | M21: USDA SR Legacy 2018-04 (NDB 18042 / FDC 174916) | N21: نعم
A22: P018 | B22: نشويات وحبوب | C22: تورتيلا دقيق | D22: Tortillas, ready-to-bake or -fry, flour, without added calcium | E22: غير محدد | F22: 325 | G22: 8.7 | H22: 55.6 | I22: 7.1 | J22: 3.3 | L22: 478 | M22: USDA SR Legacy 2018-04 (NDB 18450 / FDC 173242) | N22: نعم
A23: P019 | B23: نشويات وحبوب | C23: بطاطس مسلوقة (بدون قشر) | D23: Potatoes, boiled, cooked without skin, flesh, without salt | E23: مطبوخ | F23: 86 | G23: 1.71 | H23: 20 | I23: 0.1 | J23: 1.8 | K23: 0.89 | L23: 5 | M23: USDA SR Legacy 2018-04 (NDB 11367 / FDC 170440) | N23: نعم
A24: P020 | B24: نشويات وحبوب | C24: بطاطس مشوية (مع القشر) | D24: Potatoes, baked, flesh and skin, without salt | E24: مطبوخ | F24: 93 | G24: 2.5 | H24: 21.2 | I24: 0.13 | J24: 2.2 | K24: 1.18 | L24: 10 | M24: USDA SR Legacy 2018-04 (NDB 11674 / FDC 170093) | N24: نعم
A25: P021 | B25: نشويات وحبوب | C25: بطاطا حلوة مشوية | D25: Sweet potato, cooked, baked in skin, flesh, without salt | E25: مطبوخ | F25: 90 | G25: 2.01 | H25: 20.7 | I25: 0.15 | J25: 3.3 | K25: 6.48 | L25: 36 | M25: USDA SR Legacy 2018-04 (NDB 11508 / FDC 168483) | N25: نعم
A26: P022 | B26: نشويات وحبوب | C26: بطاطا حلوة مسلوقة | D26: Sweet potato, cooked, boiled, without skin | E26: مطبوخ | F26: 76 | G26: 1.37 | H26: 17.7 | I26: 0.14 | J26: 2.5 | K26: 5.74 | L26: 27 | M26: USDA SR Legacy 2018-04 (NDB 11510 / FDC 168484) | N26: نعم
A27: P023 | B27: نشويات وحبوب | C27: ذرة حلوة مسلوقة | D27: Corn, sweet, yellow, cooked, boiled, drained, without salt | E27: مطبوخ | F27: 96 | G27: 3.41 | H27: 21 | I27: 1.5 | J27: 2.4 | K27: 4.54 | L27: 1 | M27: USDA SR Legacy 2018-04 (NDB 11168 / FDC 169999) | N27: نعم
A28: P024 | B28: نشويات وحبوب | C28: رقائق الذرة (كورن فليكس — علامة تجارية) | D28: Cereals ready-to-eat, RALSTON Corn Flakes | E28: غير محدد | F28: 384 | G28: 5.9 | H28: 88 | I28: 0.91 | J28: 2.7 | K28: 7.84 | L28: 571 | M28: USDA SR Legacy 2018-04 (NDB 8506 / FDC 174648) | N28: نعم
A29: P025 | B29: بقوليات | C29: عدس مسلوق | D29: Lentils, mature seeds, cooked, boiled, without salt | E29: مطبوخ | F29: 116 | G29: 9.02 | H29: 20.1 | I29: 0.38 | J29: 7.9 | K29: 1.8 | L29: 2 | M29: USDA SR Legacy 2018-04 (NDB 16070 / FDC 172421) | N29: نعم
A30: P026 | B30: بقوليات | C30: عدس جاف | D30: Lentils, raw | E30: نيء | F30: 352 | G30: 24.6 | H30: 63.4 | I30: 1.06 | J30: 10.7 | K30: 2.03 | L30: 6 | M30: USDA SR Legacy 2018-04 (NDB 16069 / FDC 172420) | N30: نعم
A31: P027 | B31: بقوليات | C31: حمص مسلوق | D31: Chickpeas (garbanzo beans, bengal gram), mature seeds, cooked, boiled, without salt | E31: مطبوخ | F31: 164 | G31: 8.86 | H31: 27.4 | I31: 2.59 | J31: 7.6 | K31: 4.8 | L31: 7 | M31: USDA SR Legacy 2018-04 (NDB 16057 / FDC 173757) | N31: نعم
A32: P028 | B32: بقوليات | C32: فاصوليا حمراء (كيدني) مسلوقة | D32: Beans, kidney, red, mature seeds, cooked, boiled, without salt | E32: مطبوخ | F32: 127 | G32: 8.67 | H32: 22.8 | I32: 0.5 | J32: 7.4 | K32: 0.32 | L32: 2 | M32: USDA SR Legacy 2018-04 (NDB 16033 / FDC 175194) | N32: نعم
A33: P029 | B33: بقوليات | C33: فاصوليا سوداء مسلوقة | D33: Beans, black, mature seeds, cooked, boiled, without salt | E33: مطبوخ | F33: 132 | G33: 8.86 | H33: 23.7 | I33: 0.54 | J33: 8.7 | K33: 0.32 | L33: 1 | M33: USDA SR Legacy 2018-04 (NDB 16015 / FDC 173735) | N33: نعم
A34: P030 | B34: بقوليات | C34: فاصوليا بيضاء مسلوقة | D34: Beans, white, mature seeds, cooked, boiled, without salt | E34: مطبوخ | F34: 139 | G34: 9.73 | H34: 25.1 | I34: 0.35 | J34: 6.3 | K34: 0.34 | L34: 6 | M34: USDA SR Legacy 2018-04 (NDB 16050 / FDC 175203) | N34: نعم
... A37: P033 | B37: بقوليات | C37: حمص بالطحينة (هوموس) | D37: Hummus, commercial | E37: غير محدد | F37: 237 | G37: 7.78 | H37: 15 | I37: 17.8 | J37: 5.5 | K37: 0.62 | L37: 426 | M37: USDA SR Legacy 2018-04 (NDB 16158 / FDC 174289) | N37: نعم
A38: P034 | B38: بقوليات | C38: فلافل | D38: Falafel, home-prepared | E38: غير محدد | F38: 333 | G38: 13.3 | H38: 31.8 | I38: 17.8 | L38: 294 | M38: USDA SR Legacy 2018-04 (NDB 16138 / FDC 172455) | N38: نعم
A39: P035 | B39: بروتين | C39: صدر دجاج بلا جلد مشوي | D39: Chicken, broilers or fryers, breast, meat only, cooked, roasted | E39: مطبوخ | F39: 165 | G39: 31 | H39: 0 | I39: 3.57 | J39: 0 | K39: 0 | L39: 74 | M39: USDA SR Legacy 2018-04 (NDB 5064 / FDC 171477) | N39: نعم
A40: P036 | B40: بروتين | C40: فخذ دجاج بلا جلد مشوي | D40: Chicken, broilers or fryers, thigh, meat only, cooked, roasted | E40: مطبوخ | F40: 179 | G40: 24.8 | H40: 0 | I40: 8.15 | J40: 0 | K40: 0 | L40: 106 | M40: USDA SR Legacy 2018-04 (NDB 5098 / FDC 172388) | N40: نعم
A41: P037 | B41: بروتين | C41: صدر ديك رومي مشوي | D41: Turkey, whole, breast, meat only, cooked, roasted | E41: مطبوخ | F41: 147 | G41: 30.1 | H41: 0 | I41: 2.08 | J41: 0 | K41: 0 | L41: 99 | M41: USDA SR Legacy 2018-04 (NDB 5220 / FDC 171496) | N41: نعم
A42: P038 | B42: بروتين | C42: لحم بقري مفروم 90/10 مطبوخ | D42: Beef, ground, 90% lean meat / 10% fat, patty, cooked, broiled | E42: مطبوخ | F42: 217 | G42: 26.1 | H42: 0 | I42: 11.8 | J42: 0 | K42: 0 | L42: 68 | M42: USDA SR Legacy 2018-04 (NDB 23563 / FDC 174031) | N42: نعم
A43: P039 | B43: بروتين | C43: لحم بقري مفروم 80/20 مطبوخ | D43: Beef, ground, 80% lean meat / 20% fat, patty, cooked, broiled | E43: مطبوخ | F43: 270 | G43: 25.8 | H43: 0 | I43: 17.8 | J43: 0 | K43: 0 | L43: 75 | M43: USDA SR Legacy 2018-04 (NDB 23573 / FDC 171797) | N43: نعم
A44: P040 | B44: بروتين | C44: ستيك بقري قليل الدهن مشوي | D44: Beef, top sirloin, steak, separable lean only, trimmed to 0" fat, choice, cooked, broiled | E44: مطبوخ | F44: 188 | G44: 30.3 | H44: 0 | I44: 6.55 | J44: 0 | K44: 0 | L44: 63 | M44: USDA SR Legacy 2018-04 (NDB 13455 / FDC 168635) | N44: نعم
A45: P041 | B45: بروتين | C45: لحم غنم (ساق) قليل الدهن مشوي | D45: Lamb, leg, shank half, separable lean only, trimmed to 1/4" fat, choice, cooked, roasted | E45: مطبوخ | F45: 180 | G45: 28.2 | H45: 0 | I45: 6.67 | J45: 0 | L45: 66 | M45: USDA SR Legacy 2018-04 (NDB 17018 / FDC 172487) | N45: نعم
A46: P042 | B46: بروتين | C46: بيض كامل مسلوق | D46: Egg, whole, cooked, hard-boiled | E46: مطبوخ | F46: 155 | G46: 12.6 | H46: 1.12 | I46: 10.6 | J46: 0 | K46: 1.12 | L46: 124 | M46: USDA SR Legacy 2018-04 (NDB 1129 / FDC 173424) | N46: نعم
A47: P043 | B47: بروتين | C47: بيض كامل نيء | D47: Egg, whole, raw, fresh | E47: نيء | F47: 143 | G47: 12.6 | H47: 0.72 | I47: 9.51 | J47: 0 | K47: 0.37 | L47: 142 | M47: USDA SR Legacy 2018-04 (NDB 1123 / FDC 171287) | N47: نعم
...

Sheet Pro إعدادات
A1: Pro — الإعدادات (كلها قابلة للتعديل)
A2: القيم نقاط بداية قابلة للتعديل ضمن نطاقات منشورة (راجع المراجع بالأسفل). القرار النهائي للأخصائي.
A3: المراحل
A4: المرحلة | B4: بروتين g/kg | C4: دهون g/kg | D4: تعديل السعرات % | E4: ملاحظة
A5: بناء عضلي (فائض) | B5: 1.8 | C5: 1 | D5: 0.1 | E5: فائض أكبر؛ راقب الزيادة الدهنية
A6: بناء نظيف (فائض صغير) | B6: 2 | C6: 0.9 | D6: 0.05 | E6: فائض صغير
A7: تثبيت / صيانة | B7: 1.8 | C7: 0.9 | D7: 0
A8: إعادة تركيب الجسم | B8: 2.2 | C8: 0.8 | D8: -0.05 | E8: عجز صغير مع بروتين مرتفع
A9: تنشيف | B9: 2.4 | C9: 0.8 | D9: -0.2 | E9: يراجَع أسبوعياً حسب اتجاه الوزن والأداء
A10: ما قبل المنافسة (تنشيف متقدم) | B10: 2.6 | C10: 0.7 | D10: -0.25 | E10: بإشراف الأخصائي وبمراقبة الطاقة المتاحة
A12: أنواع الأيام
A13: نوع اليوم | B13: كربوهيدرات g/kg | C13: سعرات التدريب kcal/دقيقة (تقدير) | D13: يوم تدريب؟
A14: راحة | B14: 3 | C14: 0 | D14: لا
A15: تدريب خفيف | B15: 4 | C15: 5 | D15: نعم
A16: تدريب متوسط | B16: 5 | C16: 6 | D16: نعم
A17: تدريب ثقيل | B17: 6 | C17: 7 | D17: نعم
A18: تدريب عالٍ جداً | B18: 7 | C18: 9 | D18: نعم
A19: يوم ريفيد | B19: 6 | C19: 0 | D19: لا
A21: معاملات عامة
A22: معامل النشاط اليومي خارج التدريب (× BMR) | B22: 1.3
A23: حد أدنى للبروتين g/kg (تحذير) | B23: 1.6
A24: حد أدنى للدهون g/kg (تحذير) | B24: 0.6
A25: حد أدنى للطاقة المتاحة kcal/kg كتلة خالية (تحذير) | B25: 30
A26: الماء مل/كجم | B26: 35
A27: ماء إضافي مل لكل ساعة تدريب | B27: 500
A28: سماحية الماكروز (جرام) للتلوين | B28: 5
A29: حد أدنى للكربوهيدرات g/kg (تحذير) | B29: 2
A31: توزيع الماكروز على الوجبات (يُطبَّع تلقائياً على الوجبات الفعّالة)
A32: الوجبة | B32: الوقت | C32: فعّالة؟ | D32: راحة: بروتين % | E32: راحة: كارب % | F32: راحة: دهون % | G32: تدريب: بروتين % | H32: تدريب: كارب % | I32: تدريب: دهون %
A33: الإفطار | B33: 07:30 | C33: نعم | D33: 0.25 | E33: 0.25 | F33: 0.25 | G33: 0.2 | H33: 0.2 | I33: 0.25
A34: سناك 1 / قبل التدريب | B34: 10:30 | C34: نعم | D34: 0.1 | E34: 0.1 | F34: 0.1 | G34: 0.1 | H34: 0.15 | I34: 0.05
A35: الغداء | B35: 13:30 | C35: نعم | D35: 0.3 | E35: 0.3 | F35: 0.3 | G35: 0.25 | H35: 0.25 | I35: 0.3
A36: سناك 2 / بعد التدريب | B36: 16:30 | C36: نعم | D36: 0.1 | E36: 0.1 | F36: 0.1 | G36: 0.2 | H36: 0.25 | I36: 0.1
A37: العشاء | B37: 20:00 | C37: نعم | D37: 0.25 | E37: 0.25 | F37: 0.25 | G37: 0.25 | H37: 0.15 | I37: 0.3
A38: وجبة ليلية | B38: 22:30 | C38: لا | D38: 0 | E38: 0 | F38: 0 | G38: 0 | H38: 0 | I38: 0
A39: مجموع الفعّالة | D39: =SUMPRODUCT(--($C$33:$C$38="نعم"),D33:D38) -> 1 | E39: =SUMPRODUCT(--($C$33:$C$38="نعم"),E33:E38) -> 1 | F39: =SUMPRODUCT(--($C$33:$C$38="نعم"),F33:F38) -> 1 | G39: =SUMPRODUCT(--($C$33:$C$38="نعم"),G33:G38) -> 1 | H39: =SUMPRODUCT(--($C$33:$C$38="نعم"),H33:H38) -> 1 | I39: =SUMPRODUCT(--($C$33:$C$38="نعم"),I33:I38) -> 1
A41: مراجع نقاط البداية (راجع الأرقام والسنوات قبل الاستشهاد)
A42: • Thomas DT, Erdman KA, Burke LM. Nutrition and Athletic Performance. J Acad Nutr Diet 2016.
A43: • Jäger R et al. ISSN position stand: protein and exercise. JISSN 2017.
A44: • Helms ER, Aragon AA, Fitschen PJ. Natural bodybuilding contest preparation: nutrition and supplementation. JISSN 2014.
...

Sheet Pro إرشادات المراحل
A1: Pro — عبارات دعم وإرشادات لكل مرحلة (قابلة للتعديل)
A2: الأنواع: دعم (عبارة تشجيع تدور على صفحات الأيام) • إرشاد (قاعدة عملية في صفحة المرحلة) • توقع (ماذا نتوقع ومتى نعدّل) • تنبيه (سلامة). أضف أو عدّل أو عطّل (نشطة = لا). يختار ملف Word تلقائياً حسب المرحلة المختارة في «Pro ملف الرياضي».
A4: المرحلة | B4: النوع | C4: النص | D4: نشطة
A5: تنشيف | B5: دعم | C5: العجز المنضبط يصنع النتيجة؛ الصبر والثبات يغلبان التسرّع. | D5: نعم
A6: تنشيف | B6: دعم | C6: كل وجبة تلتزم بها اليوم هي دهن أقل غداً مع عضلاتك محفوظة. | D6: نعم
A7: تنشيف | B7: دعم | C7: الجوع جزء من الرحلة وليس علامة فشل؛ تعامل معه بالماء والخضار والبروتين. | D7: نعم
A8: تنشيف | B8: دعم | C8: لا تقارن يومك بيوم غيرك؛ قارن أسبوعك بأسبوعك الماضي. | D8: نعم
A9: تنشيف | B9: دعم | C9: قوتك في التمرين هي مؤشرك الأهم؛ إن حافظتَ عليها فأنت تحافظ على عضلاتك. | D9: نعم
A10: تنشيف | B10: دعم | C10: يوم تجاوز واحد لا يهدم أسبوعاً؛ عد للخطة في وجبتك التالية. | D10: نعم
A11: تنشيف | B11: دعم | C11: الميزان يتذبذب يومياً بسبب الماء؛ احكم على المتوسط الأسبوعي. | D11: نعم
A12: تنشيف | B12: دعم | C12: أنت أقرب إلى هدفك مما كنت عليه الأسبوع الماضي. | D12: نعم
A13: تنشيف | B13: إرشاد | C13: حافظ على شدة التمرين وأحماله قدر المستطاع؛ الإشارة للجسم أن يُبقي عضلاته. | D13: نعم
A14: تنشيف | B14: إرشاد | C14: ابدأ كل وجبة بالخضار والبروتين لتزيد الشبع. | D14: نعم
A15: تنشيف | B15: إرشاد | C15: وزّع البروتين على 3–5 وجبات متقاربة. | D15: نعم
... A102: تثبيت / صيانة | B102: تنبيه | C102: تواصل معي عند أي تغير مفاجئ في الوزن أو الشهية. | D102: نعم

Sheet Pro تفضيلات
A1: Pro — تفضيلات واستبعادات وقيود التعبئة التلقائية
A2: تستخدمها «التعبئة التلقائية» (في Diet Pro Manager أو pro_autoplan.py): تستبعد الأصناف المذكورة، وتفضّل المفضلة، وتحترم حدود التكرار وعدد الأصناف وما لا يُقدَّم معاً.
A4: أقصى مرات أسبوعياً لمصدر البروتين الواحد | B4: 5
A5: أقصى مرات أسبوعياً لأي صنف آخر | B5: 8
A6: أقصى عدد أصناف في الوجبة الواحدة | B6: 4
A7: جرامات الخضار في الغداء/العشاء | B7: 150
A8: وزن قطعة البيض (جم) للتقريب | B8: 50
M9: اكتب كلمات بينها | (مثال: سمك|روبيان). افتراضياً: لا سمك مع الألبان (قابل للحذف).
A10: أصناف مستبعدة | B10: السبب | D10: كلمات مفتاحية للاستبعاد | E10: السبب | G10: أصناف مفضلة | H10: الأولوية 1-3 | J10: صنف | K10: أقصى مرات/أسبوع | M10: لا يُقدَّم مع (مجموعة أ) | N10: لا يُقدَّم مع (مجموعة ب)
M11: سمك|سلمون|تونة|روبيان|بلطي|سردين|قد | N11: زبادي|حليب|جبنة|لبن|قريش

Sheet قوائم النظام
A1: الجنس | B1: نعم/لا | C1: مستوى التفضيل | D1: درجة التفضيل | E1: نوع الاستبعاد | F1: نيء/مطبوخ | G1: محلي/دولي | H1: مستوى الكارب | I1: طريقة الماكروز | J1: ثابت/تدوير | K1: دور المكوّن | L1: عدد الوجبات | M1: تقييم المتابعة | N1: اقتراح المتابعة | O1: خطوة الحصص | P1: فلتر نوع البروتين
A2: ذكر | B2: نعم | C2: مفضل جداً | D2: 3 | E2: حساسية | F2: نيء | G2: محلي | H2: عالٍ | I2: يدوي (نسب مئوية) | J2: ثابت | K2: بروتين رئيسي | L2: 3 | M2: نقص الوزن كما هو متوقع | N2: الإبقاء على السعرات الحالية. | O2: 0.25 | P2: الكل
A3: أنثى | B3: لا | C3: مفضل | D3: 2 | E3: عدم تحمل | F3: مطبوخ | G3: دولي | H3: متوسط | I3: تلقائي: بروتين g/kg + دهون % | J3: تدوير الكربوهيدرات | K3: كربوهيدرات رئيسي | L3: 4 | M3: نقص الوزن أبطأ من المتوقع | N3: يمكن النظر في خفض تدريجي محدود للسعرات بعد التأكد من الالتزام وقياس الوزن بشكل صحيح. | O3: 0.5 | P3: قليل الدهن
